Workbook

Sheet Summary
A1: Tour-e (YMC Tour) – TCO model summary
A2: Team model, Maruti Suzuki XCELerate 2026, E-Track. All values are live formulas; change the blue inputs on the Inputs sheet.
A4: Headline | B4: Value | C4: Sheet
A5: FLEET (80,000 km/yr, depot charging)
A6: Saving per car per year vs Ertiga CNG – Tour-e bought outright (₹ lakh) | B6: =Fleet_Economics!D7 -> 1.384 | C6: Fleet_Economics
A7: Saving per car per year vs Ertiga CNG – Tour-e + battery EMI (₹ lakh) | B7: =Fleet_Economics!C7 -> 1.224 | C7: Fleet_Economics
A8: Cost per km: CNG / Tour-e + EMI / Tour-e outright (₹) | B8: =TEXT(TCO!B30,"0.00")&" / "&TEXT(TCO!C30,"0.00")&" / "&TEXT(TCO!D30,"0.00") -> 8.86 / 7.33 / 7.13 | C8: TCO
A9: Payback of the outright price premium (months) | B9: =Fleet_Economics!D12 -> 16.603053 | C9: Fleet_Economics
A10: Battery-EMI car vs Ertiga CNG: upfront price difference (₹ lakh) | B10: =Fleet_Economics!C10 -> -1.545992 | C10: Fleet_Economics
A11: 5-year saving per car, Tour-e outright (₹ lakh) | B11: =Fleet_Economics!D8 -> 6.92 | C11: Fleet_Economics
A12: Annual saving for a 1,000-car fleet, outright / EMI (₹ crore) | B12: =TEXT(Fleet_Economics!D7*10,"0.0")&" / "&TEXT(Fleet_Economics!C7*10,"0.0") -> 13.8 / 12.2 | C12: Fleet_Economics
A13: OWNER-DRIVER (60,000 km/yr)
A14: Gain per month vs CNG, Maruti driver hub charging – EMI (₹) | B14: =Driver_Economics!C11 -> 5150 | C14: Driver_Economics
A15: Gain per month vs CNG, Maruti driver hub charging – outright (₹) | B15: =Driver_Economics!D11 -> 5600 | C15: Driver_Economics
A16: Gain per month vs CNG with no hub (EMI / outright, ₹) | B16: =Driver_Economics!E28 -> 1,400 / 1,850 | C16: Driver_Economics
A17: VEHICLE AND PRICE
A18: Ex-factory cost 2028 / 2035 (₹ lakh) | B18: =TEXT(Cost_Price!$B$18,"0.00")&" / "&TEXT(Cost_Price!$C$18,"0.00") -> 11.72 / 9.97 | C18: Cost_Price
A19: Ex-showroom outright 2028 / 2035 (₹ lakh) | B19: =TEXT(Cost_Price!$B$27,"0.00")&" / "&TEXT(Cost_Price!$C$27,"0.00") -> 13.82 / 11.76 | C19: Cost_Price
A20: Battery-EMI car price 2028 / 2035 (₹ lakh) | B20: =TEXT(Cost_Price!$B$28,"0.00")&" / "&TEXT(Cost_Price!$C$28,"0.00") -> 9.20 / 8.01 | C20: Cost_Price
A21: Battery EMI 2028 / 2035 (₹/km) · break-even at 60k km | B21: =TEXT(Inputs!$B$51,"0.0")&" / "&TEXT(Inputs!$B$52,"0.0")&" · "&TEXT(BaaS!$B$10,"0.00")&" / "&TEXT(BaaS!$C$10,"0.00") -> 2.1 / 1.7 · 2.03 / 1.65 | C21: BaaS
A22: Price walk: chosen cost sits between Ertiga and e VITARA anchors | B22: =Price_Walk!B34 -> Yes | C22: Price_Walk
A23: City range / at 70% SoH / Tour-e Long highway (km) | B23: =TEXT(BaaS!$B$29,"0")&" / "&TEXT(BaaS!$B$30,"0")&" / "&TEXT(BaaS!$B$35,"0") -> 307 / 215 / 317 | C23: BaaS
A24: STRESS AND OUTLOOK
A25: If the battery were leased (18% GST): owner-driver gain per month (₹) | B25: =Sensitivity!E63 -> 3250 | C25: Sensitivity H
A26: CNG price at which Tour-e + EMI loses its edge, owner-driver (₹/kg) | B26: =Sensitivity!E67 -> 64.4 | C26: Sensitivity G
A27: 2035: owner-driver gain per month, Tour-e + EMI (₹) | B27: =Scenario_2035!C11 -> 10000 | C27: Scenario_2035
A28: WHY MARUTI
A29: Maruti programme payback year | B29: =Maruti_Case!$B$16 -> 2033 | C29: Maruti_Case
A30: Tour-e volume in 2031 vs Maruti's EV sales today (×) | B30: =Maruti_Case!$B$20 -> 3.7741546 | C30: Maruti_Case
A32: How to use
A33: 1. Change any blue input on the Inputs sheet; every other sheet is formula-driven.
A34: 2. Sheets: Inputs → Cost_Price → Price_Walk → BaaS → TCO → Driver_Economics → Fleet_Economics → Sensitivity → Scenario_2035 → Maruti_Case → Sources.
A35: 3. Capital cost uses Excel PMT: annual loan payment at 10.5% over 5 years with the residual value as the loan's future value, plus 3% insurance on the full insured value.
A36: 4. Tour-e is the fleet version of Maruti's YMC MPV on HEARTECT-e, using the e VITARA's 49 kWh (Tour-e) and 61 kWh (Tour-e Long) LFP packs.
A37: 5. All values are in 2026 rupees with no inflation. Tour-e figures are design targets and team estimates, not current prices.
A38: 6. Road-tax / permit waivers for EVs and any state purchase incentives are excluded, so the EV case is conservative.
A39: Colour key: blue on yellow = input; black = formula; green-tinted = headline output.

Sheet Inputs
A1: Inputs & assumptions
A2: Blue cells on yellow are inputs; change them and every sheet recalculates. All money in 2026 ₹ (no inflation).
A4: Parameter | B4: Value | C4: Unit | D4: Type | E4: Source / rationale
A5: 1 · Duty cycle & finance
A6: Ownership / analysis period | B6: 5 | C6: years | D6: Team assumption | E6: Typical commercial-vehicle loan tenure and fleet holding period.
A7: Owner-driver annual km | B7: 60000 | C7: km/yr | D7: Team assumption | E7: ≈200 km/day × 300 working days; matches the 200–250 km duty day cited by EV fleet operators (slide 2).
A8: Fleet car annual km (double-shift) | B8: 80000 | C8: km/yr | D8: Team assumption | E8: ≈250 km/day × 320 days; high-utilisation fleet case.
A9: Owner-driver working days | B9: 300 | C9: days/yr | D9: Team assumption | E9: Six days a week, less holidays / servicing.
A10: Fleet working days | B10: 320 | C10: days/yr | D10: Team assumption | E10: Double-shift fleet with planned downtime.
A11: Vehicle finance rate (annual) | B11: 0.105 | C11: % | D11: Team assumption | E11: Commercial vehicle loans from banks/NBFCs typically 9.5–12%; mid-point used.
A12: Insurance, % of ex-showroom per year | B12: 0.03 | C12: %/yr | D12: Team assumption | E12: Commercial comprehensive cover for a ₹10–12 L vehicle; applied flat over 5 years (conservative).
A13: Residual value – Ertiga CNG at yr 5 | B13: 0.15 | C13: % of price | D13: Team assumption | E13: High-mileage taxi (3–4 lakh km) resale; slide 2 uses a 15–20% range.
A14: Residual value – Tour-e bought outright | B14: 0.15 | C14: % of price | D14: Team assumption | E14: Same as CNG – no EV premium assumed despite SoH passport (conservative).
A15: Residual value – Tour-e body under BaaS | B15: 0.2 | C15: % of price | D15: Team assumption | E15: Battery stays with the BaaS provider, so the buyer holds no pack-fade risk; body/eAxle retain value better.
A16: 2 · Tour-e energy (design targets)
A17: Battery pack (HEARTECT-e / e VITARA 49 kWh LFP) | B17: 49 | C17: kWh | D17: Sourced (platform) | E17: Tour-e is the fleet version of Maruti's YMC MPV and reuses the e VITARA's 49 kWh LFP pack; no new pack development.
A18: Usable battery capacity | B18: 46 | C18: kWh | D18: Team assumption | E18: ≈94% usable window, typical for LFP packs.
A19: Tour-e Long pack (e VITARA 61 kWh), usable | B19: 57 | C19: kWh | D19: Sourced (platform) | E19: 61 kWh pack at ≈94% usable.
A20: Energy use at the battery, city (real-world, AC on) | B20: 0.15 | C20: kWh/km | D20: Design target | E20: Compact MPV ~1.7 t with heavy AC use. 46 kWh ÷ 0.150 ≈ 307 km.
A21: Energy use at the battery, highway ~100 km/h | B21: 0.18 | C21: kWh/km | D21: Team assumption | E21: Tall MPV body at highway speed; used for Tour-e Long corridor range.
A22: Charging efficiency (grid → battery) | B22: 0.9 | C22: % | D22: Team assumption | E22: AC/DC charging losses of ~10%.
A23: Fleet depot / overnight tariff | B23: 9 | C23: ₹/kWh | D23: Team assumption | E23: State commercial / EV-specific tariffs are typically ₹7–10/kWh incl. fixed charges (e.g., state EV tariff orders); ₹9 used.
A24: Maruti driver hub tariff (dealer / workshop overnight) | B24: 11 | C24: ₹/kWh | D24: Team assumption | E24: Owner-drivers without a depot charge overnight at Maruti dealer and service workshops: depot tariff plus a ₹2/kWh hub margin.
A25: Public DC fast-charging tariff | B25: 20 | C25: ₹/kWh | D25: Sourced (range) | E25: Public DC CPO pricing in India 2026 is ~₹18–25/kWh incl. GST (MeraEV / MyMotor tariff guides).
A26: Fleet: share of energy charged at depot | B26: 0.8 | C26: % | D26: Team assumption | E26: Fleet model built around overnight depot charging; 20% top-ups at public DC.
A27: Owner-driver: share of energy at Maruti driver hub | B27: 0.8 | C27: % | D27: Team assumption | E27: Base case for owner-drivers; the rest at public DC.
A28: Owner-driver without hub: share at slow public chargers | B28: 0.3 | C28: % | D28: Team assumption | E28: Stress case: no hub; 30% slow public AC at the hub tariff, 70% public DC.
A29: Tour-e maintenance + tyres | B29: 0.55 | C29: ₹/km | D29: Team assumption | E29: No engine oil, filters, clutch; regen reduces brake wear. ~40–45% lower than CNG, consistent with fleet-operator reports.
A30: 3 · Ertiga Tour M CNG benchmark
A31: Ertiga Tour M CNG ex-showroom (post GST 2.0) | B31: 10.745 | C31: ₹ lakh | D31: Sourced | E31: ₹10.74 L – Maruti post-GST 2.0 price list via Autocar India; Tour M is the fleet version of India's No.1 MPV.
A32: CNG price | B32: 85 | C32: ₹/kg | D32: Sourced (rounded down) | E32: Delhi IGL ₹86.98/kg from 29 Aug 2026 (Outlook Business, Goodreturns). ₹85 is slightly conservative – it favours CNG.
A33: CNG real-world efficiency | B33: 20 | C33: km/kg | D33: Team assumption | E33: Claimed 26.11 km/kg (ARAI); city taxi duty with AC typically 18–21 km/kg.
A34: CNG maintenance + tyres | B34: 0.95 | C34: ₹/km | D34: Team assumption | E34: Engine oil/filter every 10k km, spark plugs, clutch, CNG kit servicing and hydro-testing.
A35: 4 · Cost stack & pricing
A36: Battery pack cost 2028 (landed, pack level) | B36: 8000 | C36: ₹/kWh | D36: Sourced (anchored) | E36: ≈$84/kWh × ₹95/$ – BNEF 2025 survey: China average pack price $84/kWh (global $108). Cross-check: e VITARA 49 kWh pack is priced at ~₹5 L retail incl. margins and GST.
A37: Battery pack cost 2035 | B37: 6500 | C37: ₹/kWh | D37: Team assumption | E37: ~19% below 2028 in real terms (≈3%/yr) via localised cells (ACC-PLI) and LFP scale; conservative vs. BNEF outlooks.
A38: Exchange rate | B38: 95 | C38: ₹/US$ | D38: Sourced | E38: INR traded ~₹94.6–95.4 per US$ in Jun–Aug 2026 (HDFC Sky daily market reports).
A39: OEM margin on cost | B39: 0.08 | C39: % | D39: Team assumption | E39: Mass-market OEM EBIT margins ~7–10%.
A40: Dealer margin | B40: 0.04 | C40: % | D40: Team assumption | E40: Fleet sales carry thin dealer margins (3–5%).
A41: GST on EVs (vehicle and battery sold with it) | B41: 0.05 | C41: % | D41: Sourced | E41: GST Council, GST 2.0 effective 22 Sep 2025: EVs stay at 5%.
...

Sheet Cost_Price
A1: Bottom-up cost stack & price build-up (₹ lakh per vehicle, 2026 ₹)
A2: Team estimate for a HEARTECT-e derived compact MPV. Battery line is formula-driven; other lines are inputs (blue).
A4: Cost line | B4: 2028 launch | C4: 2035 scale | D4: Change | E4: Basis
A5: Battery pack (49 kWh, e VITARA / YMC pack) | B5: =Inputs!$B$17*Inputs!$B$36/100000 -> 3.92 | C5: =Inputs!$B$17*Inputs!$B$37/100000 -> 3.185 | D5: =C5/B5-1 -> -0.1875 | E5: kWh × ₹/kWh (Inputs). 2028 ≈ BNEF China pack average.
A6: Body-in-white, paint, closures (incl. powered sliding door) | B6: 1.55 | C6: 1.4 | D6: =C6/B6-1 -> -0.096774194 | E6: YMC body; taxi version adds a powered kerb-side slider.
A7: Interior & seats (5+2, fold-flat 3rd row) | B7: 0.95 | C7: 0.85 | D7: =C7/B7-1 -> -0.10526316 | E7: Taxi-grade washable trim.
A8: Chassis, suspension, brakes, wheels | B8: 0.8 | C8: 0.72 | D8: =C8/B8-1 -> -0.1 | E8: Heavy-duty dampers and bushes for commercial duty.
A9: Low-voltage electrics & harness | B9: 0.5 | C9: 0.44 | D9: =C9/B9-1 -> -0.12 | E9: Localised harness.
A10: Safety: 6 airbags, ESP, AEB, DMS camera (ADAS-L2 optional) | B10: 0.4 | C10: 0.34 | D10: =C10/B10-1 -> -0.15 | E10: Full ADAS-L2 is a premium-trim option.
A11: eAxle (motor + inverter + reducer), reduced rare-earth | B11: 0.75 | C11: 0.6 | D11: =C11/B11-1 -> -0.2 | E11: e VITARA eAxle; largest localisation gain by 2035.
A12: HV electronics (7.4 kW OBC, DC-DC, junction box) | B12: 0.45 | C12: 0.36 | D12: =C12/B12-1 -> -0.2 | E12: Platform spec: 7.4 kW AC; CCS2 DC.
A13: Thermal: liquid-cooled pack, heat pump, roof rear AC | B13: 0.45 | C13: 0.38 | D13: =C13/B13-1 -> -0.15555556 | E13: 'India Heat Pack'.
A14: Telematics / FleetOS hardware | B14: 0.1 | C14: 0.07 | D14: =C14/B14-1 -> -0.3 | E14: 4G/5G TCU, OTA-capable.
A15: Assembly, overhead, logistics | B15: 0.85 | C15: 0.76 | D15: =C15/B15-1 -> -0.10588235 | E15: Built on the YMC line.
A16: Warranty provision | B16: 0.3 | C16: 0.25 | D16: =C16/B16-1 -> -0.16666667 | E16: Vehicle warranty (battery risk sits with the BaaS programme).
A17: R&D / tooling amortisation | B17: 0.7 | C17: 0.62 | D17: =C17/B17-1 -> -0.11428571 | E17: Recovers the programme capex (see Maruti_Case).
A18: Ex-factory cost (total) | B18: =SUM(B5:B17) -> 11.72 | C18: =SUM(C5:C17) -> 9.975 | D18: =C18/B18-1 -> -0.14889078 | E18: Sum of lines.
A19: of which battery share | B19: =B5/B18 -> 0.33447099 | C19: =C5/C18 -> 0.31929825 | D19: =C19/B19-1 -> -0.045363409
A20: Non-battery cost | B20: =B18-B5 -> 7.8 | C20: =C18-C5 -> 6.79 | D20: =C20/B20-1 -> -0.12948718
A22: Price build-up
A23: × OEM margin | B23: =Inputs!$B$39 -> 0.08 | C23: =Inputs!$B$39 -> 0.08 | D23: =C23/B23-1 -> 0 | E23: Inputs
A24: × Dealer margin | B24: =Inputs!$B$40 -> 0.04 | C24: =Inputs!$B$40 -> 0.04 | D24: =C24/B24-1 -> 0 | E24: Inputs
A25: × GST on EVs | B25: =Inputs!$B$41 -> 0.05 | C25: =Inputs!$B$41 -> 0.05 | D25: =C25/B25-1 -> 0 | E25: Inputs
A26: Price multiplier on cost | B26: =(1+Inputs!$B$39)*(1+Inputs!$B$40)*(1+Inputs!$B$41) -> 1.17936 | C26: =(1+Inputs!$B$39)*(1+Inputs!$B$40)*(1+Inputs!$B$41) -> 1.17936 | D26: =C26/B26-1 -> 0 | E26: 1.08 × 1.04 × 1.05
A27: Ex-showroom price, bought outright (₹ L) | B27: =B18*B26 -> 13.822099 | C27: =C18*C26 -> 11.764116 | D27: =C27/B27-1 -> -0.14889078 | E27: Fleet price, bought outright.
A28: Fleet BaaS: vehicle-only price (₹ L) | B28: =B20*B26 -> 9.199008 | C28: =C20*C26 -> 8.0078544 | D28: =C28/B28-1 -> -0.12948718 | E28: Battery financed separately through the per-km battery EMI.
A29: Battery price financed by the battery EMI (₹ L) | B29: =B5*(1+Inputs!$B$39)*(1+Inputs!$B$41) -> 4.44528 | C29: =C5*(1+Inputs!$B$39)*(1+Inputs!$B$41) -> 3.61179 | D29: =C29/B29-1 -> -0.1875 | E29: Pack at cost + OEM margin + 5% GST (sold with the vehicle; no dealer margin on the battery).
A30: Pack cost in US$/kWh (check) | B30: =Inputs!$B$36/Inputs!$B$38 -> 84.210526 | C30: =Inputs!$B$37/Inputs!$B$38 -> 68.421053 | D30: =C30/B30-1 -> -0.1875 | E30: BNEF 2025: China avg $84/kWh; LFP avg $81/kWh; global $108/kWh.
A32: Benchmarks (for context)
A33: Ertiga Tour M CNG ex-showroom | B33: =Inputs!$B$31 -> 10.745 | E33: Maruti post-GST price list (Autocar India).
A34: Retail e VITARA Delta – BaaS price / outright | B34: 10.99 / 15.99 | E34: Maruti Suzuki, Feb 2026. Walk from e VITARA to Tour-e: Price_Walk sheet.
A35: Tour-e 2028 outright premium over Ertiga CNG | B35: =B27-Inputs!$B$31 -> 3.0770992 | E35: Repaid by running-cost savings – see Fleet_Economics.

Sheet Price_Walk
A1: Why the Tour-e costs what it does: two anchors (₹ lakh, 2028)
A2: Anchor A starts from the Ertiga Tour M taxi; anchor B from the e VITARA Delta. The chosen non-battery cost must sit between them.
A4: Step | B4: ₹ lakh | C4: Basis
A5: Anchor A · from the Ertiga Tour M CNG (Maruti's taxi MPV today)
A6: Ertiga Tour M CNG ex-showroom | B6: =Inputs!$B$31 -> 10.745 | C6: Maruti post-GST 2.0 price list.
A7: ÷ (1 + 40% GST) | B7: =B6/(1+Inputs!$B$43) -> 7.675 | C7: GST 2.0 rate for cars over 4 m.
A8: ÷ (1 + 4% fleet dealer margin) | B8: =B7/(1+Inputs!$B$40) -> 7.3798077
A9: ÷ (1 + 8% OEM margin) = Ertiga Tour M cost | B9: =B8/(1+Inputs!$B$39) -> 6.8331553
A10: − Engine and gearbox | B10: 0.75 | C10: K15 petrol engine and 5-speed manual (team estimate).
A11: − CNG kit and cylinders | B11: 0.3 | C11: Factory CNG kit, ~60 L water-capacity cylinders.
A12: − Fuel, exhaust, cooling, starter and alternator | B12: 0.3
A13: → Glider (body, interior, chassis, electrics, assembly) | B13: =B9-SUM(B10:B12) -> 5.4831553
A14: + eAxle (motor, inverter, reducer) | B14: 0.75 | C14: e VITARA-class eAxle.
A15: + HV electronics (OBC, DC-DC, junction box) | B15: 0.45
A16: + Thermal: liquid-cooled pack, heat pump, roof rear AC | B16: 0.45 | C16: 'India Heat Pack'.
A17: + Skateboard floor and powered sliding door | B17: 0.35
A18: + AEB and driver-monitoring camera | B18: 0.2 | C18: ADAS-L2 stays optional.
A19: + Telematics (FleetOS) | B19: 0.1
A20: → Anchor A: Tour-e non-battery cost | B20: =B13+SUM(B14:B19) -> 7.7831553 | C20: Bottom-up from Maruti's current taxi.
A22: Anchor B · from the e VITARA Delta (Maruti's HEARTECT-e EV today)
A23: e VITARA Delta BaaS price (battery excluded) | B23: =Inputs!$B$56 -> 10.99 | C23: Maruti Suzuki, Feb 2026.
A24: ÷ (1 + 5% GST) | B24: =B23/(1+Inputs!$B$41) -> 10.466667
A25: ÷ (1 + 5% Nexa retail dealer margin) | B25: =B24/(1+Inputs!$B$58) -> 9.968254
A26: ÷ (1 + 8% OEM margin) = e VITARA non-battery cost | B26: =B25/(1+Inputs!$B$39) -> 9.2298648
A27: − Nexa premium content | B27: -0.7 | C27: 18-inch alloys, dual screens, premium trim and audio, ventilated seats, ambient lighting.
A28: − Launch-volume and localisation gains by 2028 | B28: -0.75 | C28: Low-volume 2026 launch with imported parts vs. 50k/yr fleet volume and localised pack, BMS and thermal.
A29: + MPV body, 3rd row, sliding door, roof rear AC | B29: 0.45
A30: → Anchor B: Tour-e non-battery cost | B30: =B26+SUM(B27:B29) -> 8.2298648 | C30: Top-down from Maruti's current EV.
A32: Result
A33: Chosen non-battery cost (Cost_Price stack) | B33: =Cost_Price!$B$20 -> 7.8 | C33: Sum of the cost lines on Cost_Price.
A34: Sits between the two anchors? | B34: =IF(AND(B33>=MIN(B20,B30),B33<=MAX(B20,B30)),"Yes","No") -> Yes | C34: Check.
A35: Tour-e outright price vs e VITARA Delta with battery (₹ L) | B35: =Cost_Price!$B$27-Inputs!$B$57 -> -2.1679008 | C35: Negative = Tour-e is cheaper: taxi spec, fleet margins and 2028 battery cost.
A36: Tour-e battery-EMI price vs e VITARA Delta BaaS price (₹ L) | B36: =Cost_Price!$B$28-Inputs!$B$56 -> -1.790992
A37: e VITARA battery value implied by Maruti's prices (₹ L) | B37: =Inputs!$B$57-Inputs!$B$56 -> 5 | C37: 15.99 − 10.99; includes 2026 cell cost, Nexa margin and GST.
A38: Tour-e battery price financed, 2028 (₹ L) | B38: =Cost_Price!$B$29 -> 4.44528 | C38: Same 49 kWh pack at 2028 cost, fleet margin, 5% GST.

Sheet BaaS
A1: Fleet battery EMI (BaaS): break-even rate
A2: Same dual-loan structure as Maruti's e VITARA BaaS: the battery is sold with the car (5% GST) and financed per km by an NBFC, with an assured buy-back at 25%.
A4: Step | B4: 2028 | C4: 2035 | D4: Formula / note
A5: Battery price financed (₹ L) | B5: =Cost_Price!$B$29 -> 4.44528 | C5: =Cost_Price!$C$29 -> 3.61179 | D5: From Cost_Price: cost + OEM margin + 5% GST.
A6: Annual capital recovery net of residual (₹ L/yr) | B6: =PMT(Inputs!$B$45,Inputs!$B$46,-B5,Inputs!$B$47*B5) -> 1.0243158 | C6: =PMT(Inputs!$B$45,Inputs!$B$46,-C5,Inputs!$B$47*C5) -> 0.83225658 | D6: PMT(11%, 5 yrs, battery price, 25% buy-back as future value).
A7: + Risk reserve | B7: =B6*Inputs!$B$48 -> 0.10243158 | C7: =C6*Inputs!$B$48 -> 0.083225658 | D7: 10% of capital recovery; funds the buy-back guarantee and early replacements.
A8: + Programme margin | B8: =(B6+B7)*Inputs!$B$49 -> 0.090139789 | C8: =(C6+C7)*Inputs!$B$49 -> 0.073238579 | D8: 8% on cost incl. reserve.
A9: Annual EMI revenue required (₹ L/yr) | B9: =B6+B7+B8 -> 1.2168872 | C9: =C6+C7+C8 -> 0.98872082
A10: Break-even at minimum contract km (₹/km) | B10: =B9*100000/Inputs!$B$50 -> 2.0281453 | C10: =C9*100000/Inputs!$B$50 -> 1.647868 | D10: Minimum contracted km: 60,000 a year.
A11: Break-even at fleet km (₹/km) | B11: =B9*100000/Inputs!$B$8 -> 1.5211089 | C11: =C9*100000/Inputs!$B$8 -> 1.235901 | D11: Upside for the programme when fleets run 80,000 km.
A12: Chosen fleet battery EMI (₹/km) | B12: =Inputs!$B$51 -> 2.1 | C12: =Inputs!$B$52 -> 1.7 | D12: Rounded up above break-even.
A13: Headroom over break-even at minimum km | B13: =B12/B10-1 -> 0.035428792 | C13: =C12/C10-1 -> 0.031636013 | D13: Must be ≥ 0.
A14: Programme margin at fleet km after costs (₹ L/yr/car) | B14: =B12*Inputs!$B$8/100000-B6-B7 -> 0.55325263 | C14: =C12*Inputs!$B$8/100000-C6-C7 -> 0.44451776 | D14: EMI revenue at 80k km minus capital recovery and reserve.
A15: For reference: same EMI if structured as a lease (incl. 18% GST) | B15: =B12*(1+Inputs!$B$42) -> 2.478 | C15: =C12*(1+Inputs!$B$42) -> 2.006 | D15: Why the loan structure matters: a lease would add 18% GST that cab operators cannot recover.
A16: Fleet tier: battery EMI for 80,000 km contracts (₹/km) | B16: =Inputs!$B$53 -> 1.7 | D16: Headroom over the 80,000 km break-even shown next.
A17: Headroom over the 80,000 km break-even | B17: =B16/B11-1 -> 0.11760568 | D17: Must be ≥ 0.
A19: Why the fleet rate is half the retail e VITARA rate
A20: Retail e VITARA BaaS (₹/km) | B20: =Inputs!$B$54 -> 3.99 | D20: Maruti Suzuki, Feb 2026.
A21: Retail usage basis (km/yr) | B21: =Inputs!$B$55 -> 21900 | D21: ~60 km/day.
A22: Fleet minimum km ÷ retail km | B22: =Inputs!$B$50/Inputs!$B$55 -> 2.739726 | D22: Same pack, ~2.7× the km → far lower ₹/km.
A23: Retail rate spread over fleet km (₹/km) | B23: =Inputs!$B$54*Inputs!$B$55/Inputs!$B$50 -> 1.45635 | D23: Pure scaling of the retail rate. The fleet EMI sits above this, so it is conservative for the programme.
A25: Battery duty check
A26: Lifetime km at fleet duty (5 yrs) | B26: =Inputs!$B$8*Inputs!$B$6 -> 400000 | D26: 4 lakh km design life.
A27: Energy throughput at battery (kWh) | B27: =B26*Inputs!$B$20 -> 60000
A28: Equivalent full cycles (usable kWh) | B28: =B27/Inputs!$B$18 -> 1304.3478 | D28: ≈1,300–1,450 equivalent full cycles over 5 years – well within LFP cycle life (automotive LFP cells are typically rated 3,000+ cycles).
A29: Real-world city range (km) | B29: =Inputs!$B$18/Inputs!$B$20 -> 306.66667 | D29: 46 kWh usable ÷ 150 Wh/km.
A30: Range at 70% SoH end-of-life (km) | B30: =Inputs!$B$18*0.7/Inputs!$B$20 -> 214.66667 | D30: Still covers a 200 km owner-driver day.
A31: Fleet day (km) | B31: =Inputs!$B$8/Inputs!$B$10 -> 250 | D31: 80,000 km ÷ 320 days.
A32: Shortfall at end of life, fleet day (km) | B32: =MAX(0,B31-B30) -> 35.333333 | D32: Covered by one DC top-up a day from about year 3.
A33: Km per day already budgeted on public DC (fleet) | B33: =(1-Inputs!$B$26)*B31 -> 50 | D33: The 20% DC share in the TCO already pays for this top-up, so no extra cost.
A34: Tour-e Long range, city (km) | B34: =Inputs!$B$19/Inputs!$B$20 -> 380 | D34: 61 kWh pack, 57 kWh usable.
A35: Tour-e Long range, highway at ~100 km/h (km) | B35: =Inputs!$B$19/Inputs!$B$21 -> 316.66667 | D35: Covers 280–300 km corridors (e.g. Delhi–Jaipur) one way; top up before the return leg.

Sheet TCO
A1: 5-year TCO per km – Tour-e vs Ertiga Tour M CNG (2028 launch prices)
A2: Capital = annualised loan cost net of residual (PMT) + insurance. Driver wage excluded. 2026 ₹.
A4: Owner-driver: annual km = | B4: =Inputs!$B$7 -> 60000
A5: OWNER-DRIVER @ 60k km/yr | B5: Ertiga CNG | C5: Tour-e + battery EMI | D5: Tour-e outright | E5: How it is calculated
A6: Energy (₹/km) | B6: =ROUND(Inputs!$B$32/Inputs!$B$33,2) -> 4.25 | C6: =ROUND(Inputs!$B$20/Inputs!$B$22*(Inputs!$B$27*Inputs!$B$24+(1-Inputs!$B$27)*Inputs!$B$25),2) -> 2.13 | D6: =ROUND(Inputs!$B$20/Inputs!$B$22*(Inputs!$B$27*Inputs!$B$24+(1-Inputs!$B$27)*Inputs!$B$25),2) -> 2.13 | E6: CNG: ₹/kg ÷ km/kg. EV: kWh/km ÷ charging eff. × blended tariff (80% Maruti driver hub ₹11, 20% public DC ₹20 = ₹12.8).
A7: Maintenance & tyres (₹/km) | B7: =Inputs!$B$34 -> 0.95 | C7: =Inputs!$B$29 -> 0.55 | D7: =Inputs!$B$29 -> 0.55 | E7: Inputs.
A8: Battery EMI (₹/km) | B8: =0 -> 0 | C8: =Inputs!$B$51 -> 2.1 | D8: =0 -> 0 | E8: Battery EMI, 2028, tiered by contracted km (a loan, so no GST on it).
A9: Upfront price (₹ lakh) | B9: =Inputs!$B$31 -> 10.745 | C9: =Cost_Price!$B$28 -> 9.199008 | D9: =Cost_Price!$B$27 -> 13.822099 | E9: Ex-showroom; battery-EMI car excludes the battery. Road-tax/permit waivers for EVs excluded (conservative).
A10: Residual at year 5 | B10: =Inputs!$B$13 -> 0.15 | C10: =Inputs!$B$15 -> 0.2 | D10: =Inputs!$B$14 -> 0.15 | E10: Inputs.
A11: Capital: annual loan cost net of residual (₹ L/yr) | B11: =PMT(Inputs!$B$11,Inputs!$B$6,-B9,B10*B9) -> 2.6094143 | C11: =PMT(Inputs!$B$11,Inputs!$B$6,-C9,C10*C9) -> 2.1593788 | D11: =PMT(Inputs!$B$11,Inputs!$B$6,-D9,D10*D9) -> 3.3566853 | E11: PMT(10.5%, 5, price, residual).
A12: Insurance (₹ L/yr) | B12: =Inputs!$B$12*B9 -> 0.32235 | C12: =Inputs!$B$12*C9+Inputs!$B$12*Cost_Price!$B$29 -> 0.40932864 | D12: =Inputs!$B$12*D9 -> 0.41466298 | E12: 3% of insured value; the battery-EMI car also insures its battery.
A13: Capital & insurance (₹/km) | B13: =ROUND((B11+B12)*100000/Inputs!$B$7,2) -> 4.89 | C13: =ROUND((C11+C12)*100000/Inputs!$B$7,2) -> 4.28 | D13: =ROUND((D11+D12)*100000/Inputs!$B$7,2) -> 6.29 | E13: (Capital + insurance) × 1e5 ÷ annual km. Each ₹/km line is shown to the paisa.
A14: TOTAL COST PER KM (₹/km) | B14: =B6+B7+B8+B13 -> 10.09 | C14: =C6+C7+C8+C13 -> 9.06 | D14: =D6+D7+D8+D13 -> 8.97 | E14: Energy + maintenance + battery + capital & insurance.
A15: Annual cost (₹ lakh/yr) | B15: =B14*Inputs!$B$7/100000 -> 6.054 | C15: =C14*Inputs!$B$7/100000 -> 5.436 | D15: =D14*Inputs!$B$7/100000 -> 5.382 | E15: ₹/km × annual km.
A16: 5-year cost (₹ lakh) | B16: =B15*Inputs!$B$6 -> 30.27 | C16: =C15*Inputs!$B$6 -> 27.18 | D16: =D15*Inputs!$B$6 -> 26.91 | E16: Annual × 5 (undiscounted cash view).
A17: Saving vs CNG (₹/km) | B17: =$B14-B14 -> 0 | C17: =$B14-C14 -> 1.03 | D17: =$B14-D14 -> 1.12
A18: Saving vs CNG (₹ lakh/yr) | B18: =B17*Inputs!$B$7/100000 -> 0 | C18: =C17*Inputs!$B$7/100000 -> 0.618 | D18: =D17*Inputs!$B$7/100000 -> 0.672
A20: Fleet: annual km = | B20: =Inputs!$B$8 -> 80000
A21: FLEET @ 80k km/yr | B21: Ertiga CNG | C21: Tour-e + battery EMI | D21: Tour-e outright | E21: How it is calculated
A22: Energy (₹/km) | B22: =ROUND(Inputs!$B$32/Inputs!$B$33,2) -> 4.25 | C22: =ROUND(Inputs!$B$20/Inputs!$B$22*(Inputs!$B$26*Inputs!$B$23+(1-Inputs!$B$26)*Inputs!$B$25),2) -> 1.87 | D22: =ROUND(Inputs!$B$20/Inputs!$B$22*(Inputs!$B$26*Inputs!$B$23+(1-Inputs!$B$26)*Inputs!$B$25),2) -> 1.87 | E22: CNG: ₹/kg ÷ km/kg. EV: kWh/km ÷ charging eff. × blended tariff (80% fleet depot ₹9, 20% public DC ₹20 = ₹11.2).
A23: Maintenance & tyres (₹/km) | B23: =Inputs!$B$34 -> 0.95 | C23: =Inputs!$B$29 -> 0.55 | D23: =Inputs!$B$29 -> 0.55 | E23: Inputs.
A24: Battery EMI (₹/km) | B24: =0 -> 0 | C24: =Inputs!$B$53 -> 1.7 | D24: =0 -> 0 | E24: Battery EMI, 2028, tiered by contracted km (a loan, so no GST on it).
A25: Upfront price (₹ lakh) | B25: =Inputs!$B$31 -> 10.745 | C25: =Cost_Price!$B$28 -> 9.199008 | D25: =Cost_Price!$B$27 -> 13.822099 | E25: Ex-showroom; battery-EMI car excludes the battery. Road-tax/permit waivers for EVs excluded (conservative).
A26: Residual at year 5 | B26: =Inputs!$B$13 -> 0.15 | C26: =Inputs!$B$15 -> 0.2 | D26: =Inputs!$B$14 -> 0.15 | E26: Inputs.
A27: Capital: annual loan cost net of residual (₹ L/yr) | B27: =PMT(Inputs!$B$11,Inputs!$B$6,-B25,B26*B25) -> 2.6094143 | C27: =PMT(Inputs!$B$11,Inputs!$B$6,-C25,C26*C25) -> 2.1593788 | D27: =PMT(Inputs!$B$11,Inputs!$B$6,-D25,D26*D25) -> 3.3566853 | E27: PMT(10.5%, 5, price, residual).
A28: Insurance (₹ L/yr) | B28: =Inputs!$B$12*B25 -> 0.32235 | C28: =Inputs!$B$12*C25+Inputs!$B$12*Cost_Price!$B$29 -> 0.40932864 | D28: =Inputs!$B$12*D25 -> 0.41466298 | E28: 3% of insured value; the battery-EMI car also insures its battery.
A29: Capital & insurance (₹/km) | B29: =ROUND((B27+B28)*100000/Inputs!$B$8,2) -> 3.66 | C29: =ROUND((C27+C28)*100000/Inputs!$B$8,2) -> 3.21 | D29: =ROUND((D27+D28)*100000/Inputs!$B$8,2) -> 4.71 | E29: (Capital + insurance) × 1e5 ÷ annual km. Each ₹/km line is shown to the paisa.
A30: TOTAL COST PER KM (₹/km) | B30: =B22+B23+B24+B29 -> 8.86 | C30: =C22+C23+C24+C29 -> 7.33 | D30: =D22+D23+D24+D29 -> 7.13 | E30: Energy + maintenance + battery + capital & insurance.
A31: Annual cost (₹ lakh/yr) | B31: =B30*Inputs!$B$8/100000 -> 7.088 | C31: =C30*Inputs!$B$8/100000 -> 5.864 | D31: =D30*Inputs!$B$8/100000 -> 5.704 | E31: ₹/km × annual km.
A32: 5-year cost (₹ lakh) | B32: =B31*Inputs!$B$6 -> 35.44 | C32: =C31*Inputs!$B$6 -> 29.32 | D32: =D31*Inputs!$B$6 -> 28.52 | E32: Annual × 5 (undiscounted cash view).
A33: Saving vs CNG (₹/km) | B33: =$B30-B30 -> 0 | C33: =$B30-C30 -> 1.53 | D33: =$B30-D30 -> 1.73
A34: Saving vs CNG (₹ lakh/yr) | B34: =B33*Inputs!$B$8/100000 -> 0 | C34: =C33*Inputs!$B$8/100000 -> 1.224 | D34: =D33*Inputs!$B$8/100000 -> 1.384
A37: Reading this sheet
A38: • Owner-drivers charge mostly at Maruti driver hubs (dealer and service workshops overnight); fleets charge at their own depots.
A39: • The battery-EMI car is financed in two loans, as with the e VITARA: the car (left) and the battery (per km). Insurance covers both.
A40: • Fleets: see Fleet_Economics. Charging access is the main swing factor for owner-drivers: see Driver_Economics.

Sheet Driver_Economics
A1: Owner-driver economics (monthly)
A2: Uplift = CNG ₹/km − Tour-e ₹/km × monthly km. It does not depend on the fare assumption.
A4: Item | B4: Ertiga CNG | C4: Tour-e + battery EMI | D4: Tour-e outright | E4: Note
A5: Monthly km | B5: =Inputs!$B$7/12 -> 5000 | C5: =Inputs!$B$7/12 -> 5000 | D5: =Inputs!$B$7/12 -> 5000 | E5: 60,000 ÷ 12 = 5,000 km.
A6: Average daily km | B6: =Inputs!$B$7/Inputs!$B$9 -> 200 | C6: =Inputs!$B$7/Inputs!$B$9 -> 200 | D6: =Inputs!$B$7/Inputs!$B$9 -> 200 | E6: vs ~307 km real range → one overnight charge per day.
A7: Vehicle cost per km (₹/km) | B7: =TCO!B14 -> 10.09 | C7: =TCO!C14 -> 9.06 | D7: =TCO!D14 -> 8.97 | E7: From TCO sheet.
A8: Monthly vehicle cost (₹) | B8: =B7*B5 -> 50450 | C8: =C7*C5 -> 45300 | D8: =D7*D5 -> 44850
A9: Net fare earnings (₹/month, illustrative) | B9: =Inputs!$B$60*Inputs!$B$7/12 -> 67500 | C9: =Inputs!$B$60*Inputs!$B$7/12 -> 67500 | D9: =Inputs!$B$60*Inputs!$B$7/12 -> 67500 | E9: ₹13.5/km net of commission × 5,000 km.
A10: Driver take-home after vehicle costs (₹/month) | B10: =B9-B8 -> 17050 | C10: =C9-C8 -> 22200 | D10: =D9-D8 -> 22650 | E10: Illustrative – depends on fare level.
A11: Uplift vs CNG (₹/month) | B11: =$B8-B8 -> 0 | C11: =$B8-C8 -> 5150 | D11: =$B8-D8 -> 5600 | E11: Base case: Maruti driver hub charging. Independent of fares.
A12: Uplift vs CNG (₹/year) | B12: =B11*12 -> 0 | C12: =C11*12 -> 61800 | D12: =D11*12 -> 67200
A13: Take-home change vs CNG | B13: =B10/$B10-1 -> 0 | C13: =C10/$B10-1 -> 0.30205279 | D13: =D10/$B10-1 -> 0.32844575 | E13: Illustrative.
A14: Upfront outlay difference vs CNG (₹ lakh) | B14: =TCO!B9-TCO!$B9 -> 0 | C14: =TCO!C9-TCO!$B9 -> -1.545992 | D14: =TCO!D9-TCO!$B9 -> 3.0770992 | E14: The battery-EMI car costs less upfront than the CNG car.
A16: Uptime check
A17: Real-world range (km) | B17: =BaaS!$B$29 -> 306.66667
A18: Owner-driver daily km | B18: =B6 -> 200
A19: Range buffer at end of owner-driver day (km) | B19: =B17-B18 -> 106.66667
A20: Fleet daily km | B20: =Inputs!$B$8/Inputs!$B$10 -> 250
A21: Range buffer at end of fleet day (km) | B21: =B17-B20 -> 56.666667
A22: A 200–250 km duty day fits on one overnight charge; a ~45 min DC top-up (10–80% at 50 kW, platform spec) covers any extra shift.
A24: Charging access decides the owner-driver case
A25: Charging scenario (owner-driver, 60k km/yr) | B25: Blended ₹/kWh | C25: Tour-e + EMI ₹/km | D25: Tour-e outright ₹/km | E25: Gain vs CNG ₹/month (EMI / outright)
A26: Own depot (like a fleet): 80% @ ₹9, 20% DC | B26: =(Inputs!$B$26*Inputs!$B$23+(1-Inputs!$B$26)*Inputs!$B$25) -> 11.2 | C26: =ROUND(Inputs!$B$20/Inputs!$B$22*(Inputs!$B$26*Inputs!$B$23+(1-Inputs!$B$26)*Inputs!$B$25),2)+Inputs!$B$29+Inputs!$B$51+TCO!C13 -> 8.8 | D26: =ROUND(Inputs!$B$20/Inputs!$B$22*(Inputs!$B$26*Inputs!$B$23+(1-Inputs!$B$26)*Inputs!$B$25),2)+Inputs!$B$29+TCO!D13 -> 8.71 | E26: =TEXT((TCO!B14-C26)*Inputs!$B$7/12,"#,##0")&" / "&TEXT((TCO!B14-D26)*Inputs!$B$7/12,"#,##0") -> 6,450 / 6,900
A27: Maruti driver hub (base): 80% @ ₹11, 20% DC | B27: =(Inputs!$B$27*Inputs!$B$24+(1-Inputs!$B$27)*Inputs!$B$25) -> 12.8 | C27: =ROUND(Inputs!$B$20/Inputs!$B$22*(Inputs!$B$27*Inputs!$B$24+(1-Inputs!$B$27)*Inputs!$B$25),2)+Inputs!$B$29+Inputs!$B$51+TCO!C13 -> 9.06 | D27: =ROUND(Inputs!$B$20/Inputs!$B$22*(Inputs!$B$27*Inputs!$B$24+(1-Inputs!$B$27)*Inputs!$B$25),2)+Inputs!$B$29+TCO!D13 -> 8.97 | E27: =TEXT((TCO!B14-C27)*Inputs!$B$7/12,"#,##0")&" / "&TEXT((TCO!B14-D27)*Inputs!$B$7/12,"#,##0") -> 5,150 / 5,600
A28: No hub: 30% slow public @ ₹11, 70% DC @ ₹20 | B28: =(Inputs!$B$28*Inputs!$B$24+(1-Inputs!$B$28)*Inputs!$B$25) -> 17.3 | C28: =ROUND(Inputs!$B$20/Inputs!$B$22*(Inputs!$B$28*Inputs!$B$24+(1-Inputs!$B$28)*Inputs!$B$25),2)+Inputs!$B$29+Inputs!$B$51+TCO!C13 -> 9.81 | D28: =ROUND(Inputs!$B$20/Inputs!$B$22*(Inputs!$B$28*Inputs!$B$24+(1-Inputs!$B$28)*Inputs!$B$25),2)+Inputs!$B$29+TCO!D13 -> 9.72 | E28: =TEXT((TCO!B14-C28)*Inputs!$B$7/12,"#,##0")&" / "&TEXT((TCO!B14-D28)*Inputs!$B$7/12,"#,##0") -> 1,400 / 1,850
A29: Without hub charging the owner-driver gain mostly disappears, which is why Maruti driver hubs are part of the proposal. Fleets are unaffected: they charge at their own depots.

Sheet Fleet_Economics
A1: Fleet operator economics (per car and per 100-car fleet, 80k km/yr)
A4: Item | B4: Ertiga CNG | C4: Tour-e + battery EMI | D4: Tour-e outright | E4: Note
A5: Cost per km (₹/km) | B5: =TCO!B30 -> 8.86 | C5: =TCO!C30 -> 7.33 | D5: =TCO!D30 -> 7.13 | E5: TCO sheet, fleet block.
A6: Annual cost per car (₹ lakh) | B6: =TCO!B31 -> 7.088 | C6: =TCO!C31 -> 5.864 | D6: =TCO!D31 -> 5.704
A7: Annual saving per car vs CNG (₹ lakh) | B7: =TCO!B34 -> 0 | C7: =TCO!C34 -> 1.224 | D7: =TCO!D34 -> 1.384 | E7: Headline: per car per year at 80,000 km.
A8: 5-year saving per car vs CNG (₹ lakh) | B8: =B7*Inputs!$B$6 -> 0 | C8: =C7*Inputs!$B$6 -> 6.12 | D8: =D7*Inputs!$B$6 -> 6.92
A9: Upfront capex per car (₹ lakh) | B9: =TCO!B25 -> 10.745 | C9: =TCO!C25 -> 9.199008 | D9: =TCO!D25 -> 13.822099
A10: Extra capex vs CNG (₹ lakh) | B10: =B9-$B9 -> 0 | C10: =C9-$B9 -> -1.545992 | D10: =D9-$B9 -> 3.0770992 | E10: Negative = cheaper upfront.
A11: Running-cost saving vs CNG (energy + maint., ₹ lakh/yr) | B11: =((TCO!$B22+TCO!$B23)-(TCO!B22+TCO!B23+TCO!B24))*Inputs!$B$8/100000 -> 0 | C11: =((TCO!$B22+TCO!$B23)-(TCO!C22+TCO!C23+TCO!C24))*Inputs!$B$8/100000 -> 0.864 | D11: =((TCO!$B22+TCO!$B23)-(TCO!D22+TCO!D23+TCO!D24))*Inputs!$B$8/100000 -> 2.224 | E11: Outright case excludes battery fee.
A12: Simple payback of extra capex (months) | B12: =IF(B10<=0,0,B10/B11*12) -> 0 | C12: =IF(C10<=0,0,C10/C11*12) -> 0 | D12: =IF(D10<=0,0,D10/D11*12) -> 16.603053 | E12: Battery-EMI car: cheaper upfront, so immediate.
A13: Fleet of N cars – annual saving (₹ crore) | B13: =B7*Inputs!$B$61/100 -> 0 | C13: =C7*Inputs!$B$61/100 -> 1.224 | D13: =D7*Inputs!$B$61/100 -> 1.384 | E13: N from Inputs.
A14: Fleet of N cars – capex (₹ crore) | B14: =B9*Inputs!$B$61/100 -> 10.745 | C14: =C9*Inputs!$B$61/100 -> 9.199008 | D14: =D9*Inputs!$B$61/100 -> 13.822099
A16: Reading the payback: battery-EMI cars cost less upfront than the Ertiga CNG (payback = 0 months); the outright Tour-e costs more upfront and repays the difference from energy and maintenance savings alone.

Sheet Sensitivity
A1: Sensitivity & stress tests (owner-driver unless stated)
A2: Each row recomputes the full ₹/km with one input changed; everything else from Inputs.
A4: A · Annual kilometres
A5: km/yr | B5: CNG ₹/km | C5: Tour-e + EMI ₹/km | D5: Tour-e outright ₹/km | E5: EMI saving ₹/month | F5: Outright saving ₹/month
A6: 40000 | B6: =(ROUND(Inputs!$B$32/Inputs!$B$33,2)+Inputs!$B$34+ROUND((PMT(Inputs!$B$11,Inputs!$B$6,-Inputs!$B$31,Inputs!$B$13*Inputs!$B$31)+Inputs!$B$12*Inputs!$B$31)*100000/$A6,2)) -> 12.53 | C6: =(ROUND(Inputs!$B$20/Inputs!$B$22*(Inputs!$B$27*Inputs!$B$24+(1-Inputs!$B$27)*Inputs!$B$25),2)+Inputs!$B$29+Inputs!$B$51+ROUND((PMT(Inputs!$B$11,Inputs!$B$6,-Cost_Price!$B$28,Inputs!$B$15*Cost_Price!$B$28)+Inputs!$B$12*Cost_Price!$B$28+Inputs!$B$12*Cost_Price!$B$29)*100000/$A6,2)) -> 11.2 | D6: =(ROUND(Inputs!$B$20/Inputs!$B$22*(Inputs!$B$27*Inputs!$B$24+(1-Inputs!$B$27)*Inputs!$B$25),2)+Inputs!$B$29+ROUND((PMT(Inputs!$B$11,Inputs!$B$6,-Cost_Price!$B$27,Inputs!$B$14*Cost_Price!$B$27)+Inputs!$B$12*Cost_Price!$B$27)*100000/$A6,2)) -> 12.11 | E6: =(B6-C6)*$A6/12 -> 4433.3333 | F6: =(B6-D6)*$A6/12 -> 1400
A7: 50000 | B7: =(ROUND(Inputs!$B$32/Inputs!$B$33,2)+Inputs!$B$34+ROUND((PMT(Inputs!$B$11,Inputs!$B$6,-Inputs!$B$31,Inputs!$B$13*Inputs!$B$31)+Inputs!$B$12*Inputs!$B$31)*100000/$A7,2)) -> 11.06 | C7: =(ROUND(Inputs!$B$20/Inputs!$B$22*(Inputs!$B$27*Inputs!$B$24+(1-Inputs!$B$27)*Inputs!$B$25),2)+Inputs!$B$29+Inputs!$B$51+ROUND((PMT(Inputs!$B$11,Inputs!$B$6,-Cost_Price!$B$28,Inputs!$B$15*Cost_Price!$B$28)+Inputs!$B$12*Cost_Price!$B$28+Inputs!$B$12*Cost_Price!$B$29)*100000/$A7,2)) -> 9.92 | D7: =(ROUND(Inputs!$B$20/Inputs!$B$22*(Inputs!$B$27*Inputs!$B$24+(1-Inputs!$B$27)*Inputs!$B$25),2)+Inputs!$B$29+ROUND((PMT(Inputs!$B$11,Inputs!$B$6,-Cost_Price!$B$27,Inputs!$B$14*Cost_Price!$B$27)+Inputs!$B$12*Cost_Price!$B$27)*100000/$A7,2)) -> 10.22 | E7: =(B7-C7)*$A7/12 -> 4750 | F7: =(B7-D7)*$A7/12 -> 3500
A8: 60000 | B8: =(ROUND(Inputs!$B$32/Inputs!$B$33,2)+Inputs!$B$34+ROUND((PMT(Inputs!$B$11,Inputs!$B$6,-Inputs!$B$31,Inputs!$B$13*Inputs!$B$31)+Inputs!$B$12*Inputs!$B$31)*100000/$A8,2)) -> 10.09 | C8: =(ROUND(Inputs!$B$20/Inputs!$B$22*(Inputs!$B$27*Inputs!$B$24+(1-Inputs!$B$27)*Inputs!$B$25),2)+Inputs!$B$29+Inputs!$B$51+ROUND((PMT(Inputs!$B$11,Inputs!$B$6,-Cost_Price!$B$28,Inputs!$B$15*Cost_Price!$B$28)+Inputs!$B$12*Cost_Price!$B$28+Inputs!$B$12*Cost_Price!$B$29)*100000/$A8,2)) -> 9.06 | D8: =(ROUND(Inputs!$B$20/Inputs!$B$22*(Inputs!$B$27*Inputs!$B$24+(1-Inputs!$B$27)*Inputs!$B$25),2)+Inputs!$B$29+ROUND((PMT(Inputs!$B$11,Inputs!$B$6,-Cost_Price!$B$27,Inputs!$B$14*Cost_Price!$B$27)+Inputs!$B$12*Cost_Price!$B$27)*100000/$A8,2)) -> 8.97 | E8: =(B8-C8)*$A8/12 -> 5150 | F8: =(B8-D8)*$A8/12 -> 5600
A9: 70000 | B9: =(ROUND(Inputs!$B$32/Inputs!$B$33,2)+Inputs!$B$34+ROUND((PMT(Inputs!$B$11,Inputs!$B$6,-Inputs!$B$31,Inputs!$B$13*Inputs!$B$31)+Inputs!$B$12*Inputs!$B$31)*100000/$A9,2)) -> 9.39 | C9: =(ROUND(Inputs!$B$20/Inputs!$B$22*(Inputs!$B$27*Inputs!$B$24+(1-Inputs!$B$27)*Inputs!$B$25),2)+Inputs!$B$29+Inputs!$B$51+ROUND((PMT(Inputs!$B$11,Inputs!$B$6,-Cost_Price!$B$28,Inputs!$B$15*Cost_Price!$B$28)+Inputs!$B$12*Cost_Price!$B$28+Inputs!$B$12*Cost_Price!$B$29)*100000/$A9,2)) -> 8.45 | D9: =(ROUND(Inputs!$B$20/Inputs!$B$22*(Inputs!$B$27*Inputs!$B$24+(1-Inputs!$B$27)*Inputs!$B$25),2)+Inputs!$B$29+ROUND((PMT(Inputs!$B$11,Inputs!$B$6,-Cost_Price!$B$27,Inputs!$B$14*Cost_Price!$B$27)+Inputs!$B$12*Cost_Price!$B$27)*100000/$A9,2)) -> 8.07 | E9: =(B9-C9)*$A9/12 -> 5483.3333 | F9: =(B9-D9)*$A9/12 -> 7700
A10: 80000 | B10: =(ROUND(Inputs!$B$32/Inputs!$B$33,2)+Inputs!$B$34+ROUND((PMT(Inputs!$B$11,Inputs!$B$6,-Inputs!$B$31,Inputs!$B$13*Inputs!$B$31)+Inputs!$B$12*Inputs!$B$31)*100000/$A10,2)) -> 8.86 | C10: =(ROUND(Inputs!$B$20/Inputs!$B$22*(Inputs!$B$27*Inputs!$B$24+(1-Inputs!$B$27)*Inputs!$B$25),2)+Inputs!$B$29+Inputs!$B$51+ROUND((PMT(Inputs!$B$11,Inputs!$B$6,-Cost_Price!$B$28,Inputs!$B$15*Cost_Price!$B$28)+Inputs!$B$12*Cost_Price!$B$28+Inputs!$B$12*Cost_Price!$B$29)*100000/$A10,2)) -> 7.99 | D10: =(ROUND(Inputs!$B$20/Inputs!$B$22*(Inputs!$B$27*Inputs!$B$24+(1-Inputs!$B$27)*Inputs!$B$25),2)+Inputs!$B$29+ROUND((PMT(Inputs!$B$11,Inputs!$B$6,-Cost_Price!$B$27,Inputs!$B$14*Cost_Price!$B$27)+Inputs!$B$12*Cost_Price!$B$27)*100000/$A10,2)) -> 7.39 | E10: =(B10-C10)*$A10/12 -> 5800 | F10: =(B10-D10)*$A10/12 -> 9800
A11: 100000 | B11: =(ROUND(Inputs!$B$32/Inputs!$B$33,2)+Inputs!$B$34+ROUND((PMT(Inputs!$B$11,Inputs!$B$6,-Inputs!$B$31,Inputs!$B$13*Inputs!$B$31)+Inputs!$B$12*Inputs!$B$31)*100000/$A11,2)) -> 8.13 | C11: =(ROUND(Inputs!$B$20/Inputs!$B$22*(Inputs!$B$27*Inputs!$B$24+(1-Inputs!$B$27)*Inputs!$B$25),2)+Inputs!$B$29+Inputs!$B$51+ROUND((PMT(Inputs!$B$11,Inputs!$B$6,-Cost_Price!$B$28,Inputs!$B$15*Cost_Price!$B$28)+Inputs!$B$12*Cost_Price!$B$28+Inputs!$B$12*Cost_Price!$B$29)*100000/$A11,2)) -> 7.35 | D11: =(ROUND(Inputs!$B$20/Inputs!$B$22*(Inputs!$B$27*Inputs!$B$24+(1-Inputs!$B$27)*Inputs!$B$25),2)+Inputs!$B$29+ROUND((PMT(Inputs!$B$11,Inputs!$B$6,-Cost_Price!$B$27,Inputs!$B$14*Cost_Price!$B$27)+Inputs!$B$12*Cost_Price!$B$27)*100000/$A11,2)) -> 6.45 | E11: =(B11-C11)*$A11/12 -> 6500 | F11: =(B11-D11)*$A11/12 -> 14000
A12: Owner-driver charging mix (Maruti driver hub). The gap widens with km.
A14: B · CNG price (₹/kg)
A15: ₹/kg | B15: CNG ₹/km | C15: Tour-e + EMI ₹/km | D15: Uplift ₹/month
A16: 65 | B16: =(ROUND($A16/Inputs!$B$33,2)+Inputs!$B$34+ROUND((PMT(Inputs!$B$11,Inputs!$B$6,-Inputs!$B$31,Inputs!$B$13*Inputs!$B$31)+Inputs!$B$12*Inputs!$B$31)*100000/Inputs!$B$7,2)) -> 9.09 | C16: =(ROUND(Inputs!$B$20/Inputs!$B$22*(Inputs!$B$27*Inputs!$B$24+(1-Inputs!$B$27)*Inputs!$B$25),2)+Inputs!$B$29+Inputs!$B$51+ROUND((PMT(Inputs!$B$11,Inputs!$B$6,-Cost_Price!$B$28,Inputs!$B$15*Cost_Price!$B$28)+Inputs!$B$12*Cost_Price!$B$28+Inputs!$B$12*Cost_Price!$B$29)*100000/Inputs!$B$7,2)) -> 9.06 | D16: =(B16-C16)*Inputs!$B$7/12 -> 150
A17: 75 | B17: =(ROUND($A17/Inputs!$B$33,2)+Inputs!$B$34+ROUND((PMT(Inputs!$B$11,Inputs!$B$6,-Inputs!$B$31,Inputs!$B$13*Inputs!$B$31)+Inputs!$B$12*Inputs!$B$31)*100000/Inputs!$B$7,2)) -> 9.59 | C17: =(ROUND(Inputs!$B$20/Inputs!$B$22*(Inputs!$B$27*Inputs!$B$24+(1-Inputs!$B$27)*Inputs!$B$25),2)+Inputs!$B$29+Inputs!$B$51+ROUND((PMT(Inputs!$B$11,Inputs!$B$6,-Cost_Price!$B$28,Inputs!$B$15*Cost_Price!$B$28)+Inputs!$B$12*Cost_Price!$B$28+Inputs!$B$12*Cost_Price!$B$29)*100000/Inputs!$B$7,2)) -> 9.06 | D17: =(B17-C17)*Inputs!$B$7/12 -> 2650
A18: 85 | B18: =(ROUND($A18/Inputs!$B$33,2)+Inputs!$B$34+ROUND((PMT(Inputs!$B$11,Inputs!$B$6,-Inputs!$B$31,Inputs!$B$13*Inputs!$B$31)+Inputs!$B$12*Inputs!$B$31)*100000/Inputs!$B$7,2)) -> 10.09 | C18: =(ROUND(Inputs!$B$20/Inputs!$B$22*(Inputs!$B$27*Inputs!$B$24+(1-Inputs!$B$27)*Inputs!$B$25),2)+Inputs!$B$29+Inputs!$B$51+ROUND((PMT(Inputs!$B$11,Inputs!$B$6,-Cost_Price!$B$28,Inputs!$B$15*Cost_Price!$B$28)+Inputs!$B$12*Cost_Price!$B$28+Inputs!$B$12*Cost_Price!$B$29)*100000/Inputs!$B$7,2)) -> 9.06 | D18: =(B18-C18)*Inputs!$B$7/12 -> 5150
A19: 95 | B19: =(ROUND($A19/Inputs!$B$33,2)+Inputs!$B$34+ROUND((PMT(Inputs!$B$11,Inputs!$B$6,-Inputs!$B$31,Inputs!$B$13*Inputs!$B$31)+Inputs!$B$12*Inputs!$B$31)*100000/Inputs!$B$7,2)) -> 10.59 | C19: =(ROUND(Inputs!$B$20/Inputs!$B$22*(Inputs!$B$27*Inputs!$B$24+(1-Inputs!$B$27)*Inputs!$B$25),2)+Inputs!$B$29+Inputs!$B$51+ROUND((PMT(Inputs!$B$11,Inputs!$B$6,-Cost_Price!$B$28,Inputs!$B$15*Cost_Price!$B$28)+Inputs!$B$12*Cost_Price!$B$28+Inputs!$B$12*Cost_Price!$B$29)*100000/Inputs!$B$7,2)) -> 9.06 | D19: =(B19-C19)*Inputs!$B$7/12 -> 7650
A20: 105 | B20: =(ROUND($A20/Inputs!$B$33,2)+Inputs!$B$34+ROUND((PMT(Inputs!$B$11,Inputs!$B$6,-Inputs!$B$31,Inputs!$B$13*Inputs!$B$31)+Inputs!$B$12*Inputs!$B$31)*100000/Inputs!$B$7,2)) -> 11.09 | C20: =(ROUND(Inputs!$B$20/Inputs!$B$22*(Inputs!$B$27*Inputs!$B$24+(1-Inputs!$B$27)*Inputs!$B$25),2)+Inputs!$B$29+Inputs!$B$51+ROUND((PMT(Inputs!$B$11,Inputs!$B$6,-Cost_Price!$B$28,Inputs!$B$15*Cost_Price!$B$28)+Inputs!$B$12*Cost_Price!$B$28+Inputs!$B$12*Cost_Price!$B$29)*100000/Inputs!$B$7,2)) -> 9.06 | D20: =(B20-C20)*Inputs!$B$7/12 -> 10150
A21: Break-even CNG price is in G.
A23: C · Share of energy from public DC (rest at Maruti driver hub)
A24: DC share | B24: Blended ₹/kWh | C24: Tour-e + EMI ₹/km | D24: CNG ₹/km | E24: Uplift ₹/month
A25: 0 | B25: =((1-$A25)*Inputs!$B$24+$A25*Inputs!$B$25) -> 11 | C25: =((Inputs!$B$20/Inputs!$B$22*((1-$A25)*Inputs!$B$24+(1-(1-$A25))*Inputs!$B$25))+Inputs!$B$29+Inputs!$B$51+((PMT(Inputs!$B$11,Inputs!$B$6,-Cost_Price!$B$28,Inputs!$B$15*Cost_Price!$B$28)+Inputs!$B$12*Cost_Price!$B$28+Inputs!$B$12*Cost_Price!$B$29)*100000/Inputs!$B$7)) -> 8.7645124 | D25: =(ROUND(Inputs!$B$32/Inputs!$B$33,2)+Inputs!$B$34+ROUND((PMT(Inputs!$B$11,Inputs!$B$6,-Inputs!$B$31,Inputs!$B$13*Inputs!$B$31)+Inputs!$B$12*Inputs!$B$31)*100000/Inputs!$B$7,2)) -> 10.09 | E25: =(D25-C25)*Inputs!$B$7/12 -> 6627.4381
A26: 0.2 | B26: =((1-$A26)*Inputs!$B$24+$A26*Inputs!$B$25) -> 12.8 | C26: =((Inputs!$B$20/Inputs!$B$22*((1-$A26)*Inputs!$B$24+(1-(1-$A26))*Inputs!$B$25))+Inputs!$B$29+Inputs!$B$51+((PMT(Inputs!$B$11,Inputs!$B$6,-Cost_Price!$B$28,Inputs!$B$15*Cost_Price!$B$28)+Inputs!$B$12*Cost_Price!$B$28+Inputs!$B$12*Cost_Price!$B$29)*100000/Inputs!$B$7)) -> 9.0645124 | D26: =(ROUND(Inputs!$B$32/Inputs!$B$33,2)+Inputs!$B$34+ROUND((PMT(Inputs!$B$11,Inputs!$B$6,-Inputs!$B$31,Inputs!$B$13*Inputs!$B$31)+Inputs!$B$12*Inputs!$B$31)*100000/Inputs!$B$7,2)) -> 10.09 | E26: =(D26-C26)*Inputs!$B$7/12 -> 5127.4381
A27: 0.5 | B27: =((1-$A27)*Inputs!$B$24+$A27*Inputs!$B$25) -> 15.5 | C27: =((Inputs!$B$20/Inputs!$B$22*((1-$A27)*Inputs!$B$24+(1-(1-$A27))*Inputs!$B$25))+Inputs!$B$29+Inputs!$B$51+((PMT(Inputs!$B$11,Inputs!$B$6,-Cost_Price!$B$28,Inputs!$B$15*Cost_Price!$B$28)+Inputs!$B$12*Cost_Price!$B$28+Inputs!$B$12*Cost_Price!$B$29)*100000/Inputs!$B$7)) -> 9.5145124 | D27: =(ROUND(Inputs!$B$32/Inputs!$B$33,2)+Inputs!$B$34+ROUND((PMT(Inputs!$B$11,Inputs!$B$6,-Inputs!$B$31,Inputs!$B$13*Inputs!$B$31)+Inputs!$B$12*Inputs!$B$31)*100000/Inputs!$B$7,2)) -> 10.09 | E27: =(D27-C27)*Inputs!$B$7/12 -> 2877.4381
A28: 0.7 | B28: =((1-$A28)*Inputs!$B$24+$A28*Inputs!$B$25) -> 17.3 | C28: =((Inputs!$B$20/Inputs!$B$22*((1-$A28)*Inputs!$B$24+(1-(1-$A28))*Inputs!$B$25))+Inputs!$B$29+Inputs!$B$51+((PMT(Inputs!$B$11,Inputs!$B$6,-Cost_Price!$B$28,Inputs!$B$15*Cost_Price!$B$28)+Inputs!$B$12*Cost_Price!$B$28+Inputs!$B$12*Cost_Price!$B$29)*100000/Inputs!$B$7)) -> 9.8145124 | D28: =(ROUND(Inputs!$B$32/Inputs!$B$33,2)+Inputs!$B$34+ROUND((PMT(Inputs!$B$11,Inputs!$B$6,-Inputs!$B$31,Inputs!$B$13*Inputs!$B$31)+Inputs!$B$12*Inputs!$B$31)*100000/Inputs!$B$7,2)) -> 10.09 | E28: =(D28-C28)*Inputs!$B$7/12 -> 1377.4381
A29: 1 | B29: =((1-$A29)*Inputs!$B$24+$A29*Inputs!$B$25) -> 20 | C29: =((Inputs!$B$20/Inputs!$B$22*((1-$A29)*Inputs!$B$24+(1-(1-$A29))*Inputs!$B$25))+Inputs!$B$29+Inputs!$B$51+((PMT(Inputs!$B$11,Inputs!$B$6,-Cost_Price!$B$28,Inputs!$B$15*Cost_Price!$B$28)+Inputs!$B$12*Cost_Price!$B$28+Inputs!$B$12*Cost_Price!$B$29)*100000/Inputs!$B$7)) -> 10.264512 | D29: =(ROUND(Inputs!$B$32/Inputs!$B$33,2)+Inputs!$B$34+ROUND((PMT(Inputs!$B$11,Inputs!$B$6,-Inputs!$B$31,Inputs!$B$13*Inputs!$B$31)+Inputs!$B$12*Inputs!$B$31)*100000/Inputs!$B$7,2)) -> 10.09 | E29: =(D29-C29)*Inputs!$B$7/12 -> -872.56186
A30: Public DC tariff at which Tour-e loses its edge is in G.
A32: D · Battery EMI (₹/km)
A33: ₹/km | B33: Tour-e + EMI ₹/km | C33: CNG ₹/km | D33: Uplift ₹/month
A34: 1.6 | B34: =(ROUND(Inputs!$B$20/Inputs!$B$22*(Inputs!$B$27*Inputs!$B$24+(1-Inputs!$B$27)*Inputs!$B$25),2)+Inputs!$B$29+$A34+ROUND((PMT(Inputs!$B$11,Inputs!$B$6,-Cost_Price!$B$28,Inputs!$B$15*Cost_Price!$B$28)+Inputs!$B$12*Cost_Price!$B$28+Inputs!$B$12*Cost_Price!$B$29)*100000/Inputs!$B$7,2)) -> 8.56 | C34: =(ROUND(Inputs!$B$32/Inputs!$B$33,2)+Inputs!$B$34+ROUND((PMT(Inputs!$B$11,Inputs!$B$6,-Inputs!$B$31,Inputs!$B$13*Inputs!$B$31)+Inputs!$B$12*Inputs!$B$31)*100000/Inputs!$B$7,2)) -> 10.09 | D34: =(C34-B34)*Inputs!$B$7/12 -> 7650
A35: 1.8 | B35: =(ROUND(Inputs!$B$20/Inputs!$B$22*(Inputs!$B$27*Inputs!$B$24+(1-Inputs!$B$27)*Inputs!$B$25),2)+Inputs!$B$29+$A35+ROUND((PMT(Inputs!$B$11,Inputs!$B$6,-Cost_Price!$B$28,Inputs!$B$15*Cost_Price!$B$28)+Inputs!$B$12*Cost_Price!$B$28+Inputs!$B$12*Cost_Price!$B$29)*100000/Inputs!$B$7,2)) -> 8.76 | C35: =(ROUND(Inputs!$B$32/Inputs!$B$33,2)+Inputs!$B$34+ROUND((PMT(Inputs!$B$11,Inputs!$B$6,-Inputs!$B$31,Inputs!$B$13*Inputs!$B$31)+Inputs!$B$12*Inputs!$B$31)*100000/Inputs!$B$7,2)) -> 10.09 | D35: =(C35-B35)*Inputs!$B$7/12 -> 6650
A36: 2 | B36: =(ROUND(Inputs!$B$20/Inputs!$B$22*(Inputs!$B$27*Inputs!$B$24+(1-Inputs!$B$27)*Inputs!$B$25),2)+Inputs!$B$29+$A36+ROUND((PMT(Inputs!$B$11,Inputs!$B$6,-Cost_Price!$B$28,Inputs!$B$15*Cost_Price!$B$28)+Inputs!$B$12*Cost_Price!$B$28+Inputs!$B$12*Cost_Price!$B$29)*100000/Inputs!$B$7,2)) -> 8.96 | C36: =(ROUND(Inputs!$B$32/Inputs!$B$33,2)+Inputs!$B$34+ROUND((PMT(Inputs!$B$11,Inputs!$B$6,-Inputs!$B$31,Inputs!$B$13*Inputs!$B$31)+Inputs!$B$12*Inputs!$B$31)*100000/Inputs!$B$7,2)) -> 10.09 | D36: =(C36-B36)*Inputs!$B$7/12 -> 5650
A37: 2.5 | B37: =(ROUND(Inputs!$B$20/Inputs!$B$22*(Inputs!$B$27*Inputs!$B$24+(1-Inputs!$B$27)*Inputs!$B$25),2)+Inputs!$B$29+$A37+ROUND((PMT(Inputs!$B$11,Inputs!$B$6,-Cost_Price!$B$28,Inputs!$B$15*Cost_Price!$B$28)+Inputs!$B$12*Cost_Price!$B$28+Inputs!$B$12*Cost_Price!$B$29)*100000/Inputs!$B$7,2)) -> 9.46 | C37: =(ROUND(Inputs!$B$32/Inputs!$B$33,2)+Inputs!$B$34+ROUND((PMT(Inputs!$B$11,Inputs!$B$6,-Inputs!$B$31,Inputs!$B$13*Inputs!$B$31)+Inputs!$B$12*Inputs!$B$31)*100000/Inputs!$B$7,2)) -> 10.09 | D37: =(C37-B37)*Inputs!$B$7/12 -> 3150
A38: 3 | B38: =(ROUND(Inputs!$B$20/Inputs!$B$22*(Inputs!$B$27*Inputs!$B$24+(1-Inputs!$B$27)*Inputs!$B$25),2)+Inputs!$B$29+$A38+ROUND((PMT(Inputs!$B$11,Inputs!$B$6,-Cost_Price!$B$28,Inputs!$B$15*Cost_Price!$B$28)+Inputs!$B$12*Cost_Price!$B$28+Inputs!$B$12*Cost_Price!$B$29)*100000/Inputs!$B$7,2)) -> 9.96 | C38: =(ROUND(Inputs!$B$32/Inputs!$B$33,2)+Inputs!$B$34+ROUND((PMT(Inputs!$B$11,Inputs!$B$6,-Inputs!$B$31,Inputs!$B$13*Inputs!$B$31)+Inputs!$B$12*Inputs!$B$31)*100000/Inputs!$B$7,2)) -> 10.09 | D38: =(C38-B38)*Inputs!$B$7/12 -> 650
A39: 3.99 | B39: =(ROUND(Inputs!$B$20/Inputs!$B$22*(Inputs!$B$27*Inputs!$B$24+(1-Inputs!$B$27)*Inputs!$B$25),2)+Inputs!$B$29+$A39+ROUND((PMT(Inputs!$B$11,Inputs!$B$6,-Cost_Price!$B$28,Inputs!$B$15*Cost_Price!$B$28)+Inputs!$B$12*Cost_Price!$B$28+Inputs!$B$12*Cost_Price!$B$29)*100000/Inputs!$B$7,2)) -> 10.95 | C39: =(ROUND(Inputs!$B$32/Inputs!$B$33,2)+Inputs!$B$34+ROUND((PMT(Inputs!$B$11,Inputs!$B$6,-Inputs!$B$31,Inputs!$B$13*Inputs!$B$31)+Inputs!$B$12*Inputs!$B$31)*100000/Inputs!$B$7,2)) -> 10.09 | D39: =(C39-B39)*Inputs!$B$7/12 -> -4300
A40: Break-even battery EMI is in G.
A42: E · Real-world energy use (kWh/km)
A43: kWh/km | B43: Range on 46 kWh usable (km) | C43: Tour-e + EMI ₹/km | D43: Uplift ₹/month
A44: 0.13 | B44: =Inputs!$B$18/$A44 -> 353.84615 | C44: =(ROUND($A44/Inputs!$B$22*(Inputs!$B$27*Inputs!$B$24+(1-Inputs!$B$27)*Inputs!$B$25),2)+Inputs!$B$29+Inputs!$B$51+ROUND((PMT(Inputs!$B$11,Inputs!$B$6,-Cost_Price!$B$28,Inputs!$B$15*Cost_Price!$B$28)+Inputs!$B$12*Cost_Price!$B$28+Inputs!$B$12*Cost_Price!$B$29)*100000/Inputs!$B$7,2)) -> 8.78 | D44: =((ROUND(Inputs!$B$32/Inputs!$B$33,2)+Inputs!$B$34+ROUND((PMT(Inputs!$B$11,Inputs!$B$6,-Inputs!$B$31,Inputs!$B$13*Inputs!$B$31)+Inputs!$B$12*Inputs!$B$31)*100000/Inputs!$B$7,2))-C44)*Inputs!$B$7/12 -> 6550
A45: 0.15 | B45: =Inputs!$B$18/$A45 -> 306.66667 | C45: =(ROUND($A45/Inputs!$B$22*(Inputs!$B$27*Inputs!$B$24+(1-Inputs!$B$27)*Inputs!$B$25),2)+Inputs!$B$29+Inputs!$B$51+ROUND((PMT(Inputs!$B$11,Inputs!$B$6,-Cost_Price!$B$28,Inputs!$B$15*Cost_Price!$B$28)+Inputs!$B$12*Cost_Price!$B$28+Inputs!$B$12*Cost_Price!$B$29)*100000/Inputs!$B$7,2)) -> 9.06 | D45: =((ROUND(Inputs!$B$32/Inputs!$B$33,2)+Inputs!$B$34+ROUND((PMT(Inputs!$B$11,Inputs!$B$6,-Inputs!$B$31,Inputs!$B$13*Inputs!$B$31)+Inputs!$B$12*Inputs!$B$31)*100000/Inputs!$B$7,2))-C45)*Inputs!$B$7/12 -> 5150
...

Sheet Scenario_2035
A1: 2035 at scale – same duty cycle, 2035 prices (2026 ₹)
A2: Energy, CNG and maintenance held at 2026 levels; only vehicle price and BaaS rate change.
A4: Item (60k km/yr, Maruti driver hub) | B4: Ertiga CNG | C4: Tour-e + EMI 2035 | D4: Tour-e outright 2035 | E4: Note
A5: Energy (₹/km) | B5: =TCO!B6 -> 4.25 | C5: =TCO!C6 -> 2.13 | D5: =TCO!D6 -> 2.13
A6: Maintenance (₹/km) | B6: =TCO!B7 -> 0.95 | C6: =TCO!C7 -> 0.55 | D6: =TCO!D7 -> 0.55
A7: Battery EMI (₹/km) | B7: =0 -> 0 | C7: =Inputs!$B$52 -> 1.7 | D7: =0 -> 0
A8: Upfront price (₹ lakh) | B8: =Inputs!$B$31 -> 10.745 | C8: =Cost_Price!$C$28 -> 8.0078544 | D8: =Cost_Price!$C$27 -> 11.764116
A9: Capital & insurance (₹/km) | B9: =ROUND((PMT(Inputs!$B$11,Inputs!$B$6,-B8,Inputs!$B$13*B8)+Inputs!$B$12*B8)*100000/Inputs!$B$7,2) -> 4.89 | C9: =ROUND((PMT(Inputs!$B$11,Inputs!$B$6,-C8,Inputs!$B$15*C8)+Inputs!$B$12*C8+Inputs!$B$12*Cost_Price!$C$29)*100000/Inputs!$B$7,2) -> 3.71 | D9: =ROUND((PMT(Inputs!$B$11,Inputs!$B$6,-D8,Inputs!$B$14*D8)+Inputs!$B$12*D8)*100000/Inputs!$B$7,2) -> 5.35
A10: TOTAL (₹/km) | B10: =B5+B6+B7+B9 -> 10.09 | C10: =C5+C6+C7+C9 -> 8.09 | D10: =D5+D6+D7+D9 -> 8.03
A11: Uplift vs CNG (₹/month) | B11: =0 -> 0 | C11: =(B10-C10)*Inputs!$B$7/12 -> 10000 | D11: =(B10-D10)*Inputs!$B$7/12 -> 10300
A13: ="By 2035 the Tour-e with battery EMI runs ₹"&TEXT(B10-C10,"0.0")&"/km below the CNG benchmark: about ₹"&TEXT(C11/1000,"0.0")&"k a month for an owner-driver (Maruti driver hub charging)." -> By 2035 the Tour-e with battery EMI runs ₹2.0/km below the CNG benchmark: about ₹10.0k a month for an owner-driver (Maruti driver hub charging).

Sheet Maruti_Case
A1: What Maruti invests and when it pays back (team estimate, 2026 ₹)
A2: Volumes are targets. Per-unit cost moves in a straight line from the 2028 to the 2035 cost stack.
A4: Item | B4: 2028 | C4: 2029 | D4: 2030 | E4: 2031 | F4: 2032 | G4: 2033 | H4: 2034 | I4: 2035 | J4: Note
A5: Volume (units) | B5: 10000 | C5: 25000 | D5: 40000 | E5: 50000 | F5: 65000 | G5: 80000 | H5: 90000 | I5: 100000 | J5: Pilot fleets 2026–28; ~50k/yr by 2031; ≥1 lakh/yr by 2035.
A6: Ex-factory cost per unit (₹ L) | B6: =Cost_Price!$B$18+(Cost_Price!$C$18-Cost_Price!$B$18)*0.0 -> 11.72 | C6: =Cost_Price!$B$18+(Cost_Price!$C$18-Cost_Price!$B$18)*0.14285714285714285 -> 11.470714 | D6: =Cost_Price!$B$18+(Cost_Price!$C$18-Cost_Price!$B$18)*0.2857142857142857 -> 11.221429 | E6: =Cost_Price!$B$18+(Cost_Price!$C$18-Cost_Price!$B$18)*0.42857142857142855 -> 10.972143 | F6: =Cost_Price!$B$18+(Cost_Price!$C$18-Cost_Price!$B$18)*0.5714285714285714 -> 10.722857 | G6: =Cost_Price!$B$18+(Cost_Price!$C$18-Cost_Price!$B$18)*0.7142857142857143 -> 10.473571 | H6: =Cost_Price!$B$18+(Cost_Price!$C$18-Cost_Price!$B$18)*0.8571428571428571 -> 10.224286 | I6: =Cost_Price!$B$18+(Cost_Price!$C$18-Cost_Price!$B$18)*1.0 -> 9.975
A7: R&D / tooling recovery per unit (₹ L) | B7: =Cost_Price!$B$17+(Cost_Price!$C$17-Cost_Price!$B$17)*0.0 -> 0.7 | C7: =Cost_Price!$B$17+(Cost_Price!$C$17-Cost_Price!$B$17)*0.14285714285714285 -> 0.68857143 | D7: =Cost_Price!$B$17+(Cost_Price!$C$17-Cost_Price!$B$17)*0.2857142857142857 -> 0.67714286 | E7: =Cost_Price!$B$17+(Cost_Price!$C$17-Cost_Price!$B$17)*0.42857142857142855 -> 0.66571429 | F7: =Cost_Price!$B$17+(Cost_Price!$C$17-Cost_Price!$B$17)*0.5714285714285714 -> 0.65428571 | G7: =Cost_Price!$B$17+(Cost_Price!$C$17-Cost_Price!$B$17)*0.7142857142857143 -> 0.64285714 | H7: =Cost_Price!$B$17+(Cost_Price!$C$17-Cost_Price!$B$17)*0.8571428571428571 -> 0.63142857 | I7: =Cost_Price!$B$17+(Cost_Price!$C$17-Cost_Price!$B$17)*1.0 -> 0.62 | J7: The R&D / tooling line in the cost stack repays the programme capex.
A8: OEM margin per unit (₹ L) | B8: =B6*Inputs!$B$39 -> 0.9376 | C8: =C6*Inputs!$B$39 -> 0.91765714 | D8: =D6*Inputs!$B$39 -> 0.89771429 | E8: =E6*Inputs!$B$39 -> 0.87777143 | F8: =F6*Inputs!$B$39 -> 0.85782857 | G8: =G6*Inputs!$B$39 -> 0.83788571 | H8: =H6*Inputs!$B$39 -> 0.81794286 | I8: =I6*Inputs!$B$39 -> 0.798
A9: Revenue at ex-factory price (₹ crore) | B9: =B5*B6*(1+Inputs!$B$39)/100 -> 1265.76 | C9: =C5*C6*(1+Inputs!$B$39)/100 -> 3097.0929 | D9: =D5*D6*(1+Inputs!$B$39)/100 -> 4847.6571 | E9: =E5*E6*(1+Inputs!$B$39)/100 -> 5924.9571 | F9: =F5*F6*(1+Inputs!$B$39)/100 -> 7527.4457 | G9: =G5*G6*(1+Inputs!$B$39)/100 -> 9049.1657 | H9: =H5*H6*(1+Inputs!$B$39)/100 -> 9938.0057 | I9: =I5*I6*(1+Inputs!$B$39)/100 -> 10773
A10: OEM margin (₹ crore) | B10: =B5*B8/100 -> 93.76 | C10: =C5*C8/100 -> 229.41429 | D10: =D5*D8/100 -> 359.08571 | E10: =E5*E8/100 -> 438.88571 | F10: =F5*F8/100 -> 557.58857 | G10: =G5*G8/100 -> 670.30857 | H10: =H5*H8/100 -> 736.14857 | I10: =I5*I8/100 -> 798
A11: Capex recovered in the year (₹ crore) | B11: =B5*B7/100 -> 70 | C11: =C5*C7/100 -> 172.14286 | D11: =D5*D7/100 -> 270.85714 | E11: =E5*E7/100 -> 332.85714 | F11: =F5*F7/100 -> 425.28571 | G11: =G5*G7/100 -> 514.28571 | H11: =H5*H7/100 -> 568.28571 | I11: =I5*I7/100 -> 620
A12: Cumulative capex recovered (₹ crore) | B12: =SUM($B11:B11) -> 70 | C12: =SUM($B11:C11) -> 242.14286 | D12: =SUM($B11:D11) -> 513 | E12: =SUM($B11:E11) -> 845.85714 | F12: =SUM($B11:F11) -> 1271.1429 | G12: =SUM($B11:G11) -> 1785.4286 | H12: =SUM($B11:H11) -> 2353.7143 | I12: =SUM($B11:I11) -> 2973.7143
A13: Year capex is fully recovered | B13: =IF(B12>=Inputs!$B$65,2028,"") | C13: =IF(C12>=Inputs!$B$65,2029,"") | D13: =IF(D12>=Inputs!$B$65,2030,"") | E13: =IF(E12>=Inputs!$B$65,2031,"") | F13: =IF(F12>=Inputs!$B$65,2032,"") | G13: =IF(G12>=Inputs!$B$65,2033,"") -> 2033 | H13: =IF(H12>=Inputs!$B$65,2034,"") -> 2034 | I13: =IF(I12>=Inputs!$B$65,2035,"") -> 2035
A15: Programme capex (₹ crore) | B15: =Inputs!$B$65 -> 1500
A16: Payback year (capex fully recovered) | B16: =MIN(B13:I13) -> 2033
A17: Cumulative units to payback | B17: =Inputs!$B$65*100/Cost_Price!$B$17 -> 214285.71
A18: Cumulative OEM margin 2028–35 (₹ crore) | B18: =SUM(B10:I10) -> 3883.1914
A19: Maruti EV sales today, annualised (units) | B19: =Inputs!$B$63*12 -> 13248 | C19: Sep 2026 run-rate × 12.
A20: Tour-e volume in 2031 vs Maruti's EV sales today | B20: =E5/B19 -> 3.7741546 | C20: Tour-e alone would multiply Maruti's EV volume.
A21: CAFE III credit-equivalent units in 2031 | B21: =E5*Inputs!$B$64 -> 150000 | C21: Each battery EV counts 3× toward CAFE III compliance.
A23: Not counted (upside): battery-EMI programme margin, FleetOS subscriptions, driver-hub charging margin, service and parts revenue, and the CAFE III credit value.

Sheet Sources
A1: Sources used in the model
A2: Accessed Sep–Oct 2026. Team assumptions are labelled on the Inputs sheet.
A4: # | B4: Source | C4: Data used | D4: Link
A5: 1 | B5: Maruti Suzuki press release (Feb 2026) | C5: e VITARA BaaS ₹10.99 L + ₹3.99/km; retail BaaS usage basis | D5: https://www.marutisuzuki.com/corporate/media/press-releases/2026/february/india-goes-electric-with-maruti-suzuki-e-vitara-introductory-baas-price-starts
A6: 2 | B6: Autocar India – BaaS prices of e Vitara explained | C6: Pack value ~₹5 L (49 kWh); 1,800 km/month minimum | D6: https://www.autocarindia.com/auto-features/baas-prices-of-maruti-e-vitara-explained-440247
A7: 3 | B7: Autocar India – Maruti prices after GST cuts (Sep 2025) | C7: Ertiga Tour M CNG post-GST ex-showroom | D7: https://www.autocarindia.com/car-news-amp/maruti-suzuki-prices-after-gst-cuts-the-swift-gets-a-lakh-cheaper-437189
A8: 4 | B8: Outlook Business – Delhi CNG ₹86.98/kg | C8: CNG price, Aug–Sep 2026 | D8: https://www.outlookbusiness.com/economy-and-policy/delhi-cng-to-cost-8698kg-as-igl-passes-on-rising-lng-costs
A9: 5 | B9: BloombergNEF – 2025 battery price survey | C9: Pack prices: global $108/kWh; China $84/kWh; LFP $81/kWh | D9: https://about.bnef.com/insights/clean-transport/lithium-ion-battery-pack-prices-fall-to-108-per-kilowatt-hour-despite-rising-metal-prices-bloombergnef/
A10: 6 | B10: ClearTax – GST on cars (GST 2.0) | C10: EV 5%; >4 m petrol/CNG 40%, from 22 Sep 2025 | D10: https://cleartax.in/s/gst-on-cars
A11: 7 | B11: CEEW (2025) – Cost of ownership for road transport | C11: EVs cheapest-to-own taxi option; CNG next | D11: https://www.ceew.in/publications/cost-of-ownership-for-road-transport-sector-for-different-vehicle-segments-fuels-and-powertrains
A12: 8 | B12: MeraEV – EV charging cost in India (2026) | C12: Public DC tariff range | D12: https://www.meraev.com/blog/ev-charging-cost-in-india-full-guide
A13: 9 | B13: MyMotor – state-wise EV charging tariffs | C13: Depot / EV tariff range | D13: https://www.mymotor.in/blog/ev-charging-cost-india-state-wise-tariff
A14: 10 | B14: HDFC Sky – INR/USD daily reports (Jun–Aug 2026) | C14: Exchange rate ~₹95/$ | D14: https://hdfcsky.com/news/inr-usd-rate-august-11-2026-rupee-falls-95-43
A15: 11 | B15: Rushlane – Ertiga CNG launch | C15: Claimed 26.11 km/kg CNG efficiency | D15: https://www.rushlane.com/2019-maruti-ertiga-cng-launched-12318513.html
