Workbook

Sheet Summary
A1: Tour-e – TCO model summary
A2: Team model supporting the 2-slide submission (Maruti Suzuki XCELerate 2026, E-Track). All values are live formulas.
A4: Headline | B4: Model | C4: On slides | D4: Sheet
A5: Tour-e + BaaS cost per km, 60k km/yr (₹/km) | B5: =TCO!C14 -> 7.91 | C5: ₹7.9 | D5: TCO
A6: Ertiga Tour M CNG cost per km, 60k km/yr (₹/km) | B6: =TCO!B14 -> 10.09 | C6: ₹10.1 | D6: TCO
A7: Tour-e outright cost per km, 60k km/yr (₹/km) | B7: =TCO!D14 -> 8.07 | C7: ₹8.1 | D7: TCO
A8: Owner-driver uplift (₹/month) | B8: =Driver_Economics!C11 -> 10900 | C8: +₹10.9k | D8: Driver_Economics
A9: Fleet saving per car, BaaS, 80k km (₹ lakh/yr) | B9: =Fleet_Economics!C7 -> 1.464 | C9: ₹1.5 L | D9: Fleet_Economics
A10: Fleet saving per car, outright, 80k km (₹ lakh/yr) | B10: =Fleet_Economics!D7 -> 1.76 | C10: ₹1.8 L | D10: Fleet_Economics
A11: Payback of outright premium (months) | B11: =Fleet_Economics!D12 -> 9.0941784 | C11: ~9 | D11: Fleet_Economics
A12: Ex-factory cost 2028 / 2035 (₹ lakh) | B12: =TEXT(Cost_Price!$B$18,"0.00")&" / "&TEXT(Cost_Price!$C$18,"0.00") -> 10.54 / 8.96 | C12: 10.5 / 9.0 | D12: Cost_Price
A13: Ex-showroom outright 2028 / 2035 (₹ lakh) | B13: =TEXT(Cost_Price!$B$27,"0.00")&" / "&TEXT(Cost_Price!$C$27,"0.00") -> 12.43 / 10.57 | C13: 12.4 / 10.6 | D13: Cost_Price
A14: BaaS vehicle-only price 2028 / 2035 (₹ lakh) | B14: =TEXT(Cost_Price!$B$28,"0.00")&" / "&TEXT(Cost_Price!$C$28,"0.00") -> 7.90 / 6.89 | C14: 7.9 / 6.9 | D14: Cost_Price
A15: BaaS break-even @60k km 2028 / 2035 (₹/km) | B15: =TEXT(BaaS!$B$10,"0.00")&" / "&TEXT(BaaS!$C$10,"0.00") -> 1.89 / 1.54 | C15: 1.89 / 1.54 | D15: BaaS
A16: Real-world range (km) | B16: =BaaS!$B$26 -> 300 | C16: ~300 | D16: BaaS
A17: Stress: CNG at ₹75/kg – uplift (₹/month) | B17: =Sensitivity!D17 -> 8400 | C17: +₹8.4k | D17: Sensitivity B
A18: Stress: 50% public DC – Tour-e BaaS (₹/km) | B18: =Sensitivity!C27 -> 8.4531706 | C18: ₹8.45 | D18: Sensitivity C
A19: 2035: Tour-e + BaaS cost per km (₹/km) | B19: =Scenario_2035!C10 -> 7.06 | C19: Roadmap | D19: Scenario_2035
A21: How to use
A22: 1. Change any blue input on the Inputs sheet; every other sheet is formula-driven.
A23: 2. Sheets: Inputs → Cost_Price → BaaS → TCO → Driver_Economics → Fleet_Economics → Sensitivity → Scenario_2035 → Sources.
A24: 3. Capital cost uses Excel PMT: annual loan payment at 10.5% over 5 years with the residual value as the loan's future value, plus 3% insurance.
A25: 4. All values are in 2026 rupees with no inflation. Tour-e figures are design targets and team estimates, not current prices.
A26: 5. Road-tax / permit waivers for EVs and any state purchase incentives are excluded, so the EV case is conservative.
A27: Colour key: blue on yellow = input; black = formula; green-tinted = headline output.

Sheet Inputs
A1: Inputs & assumptions
A2: Blue cells on yellow are inputs; change them and every sheet recalculates. All money in 2026 ₹ (no inflation).
A4: Parameter | B4: Value | C4: Unit | D4: Type | E4: Source / rationale
A5: 1 · Duty cycle & finance
A6: Ownership / analysis period | B6: 5 | C6: years | D6: Team assumption | E6: Typical commercial-vehicle loan tenure and fleet holding period.
A7: Owner-driver annual km | B7: 60000 | C7: km/yr | D7: Team assumption | E7: ≈200 km/day × 300 working days; matches the 200–250 km duty day cited by EV fleet operators (slide 2).
A8: Fleet car annual km (double-shift) | B8: 80000 | C8: km/yr | D8: Team assumption | E8: ≈250 km/day × 320 days; high-utilisation fleet case.
A9: Owner-driver working days | B9: 300 | C9: days/yr | D9: Team assumption | E9: Six days a week, less holidays / servicing.
A10: Fleet working days | B10: 320 | C10: days/yr | D10: Team assumption | E10: Double-shift fleet with planned downtime.
A11: Vehicle finance rate (annual) | B11: 0.105 | C11: % | D11: Team assumption | E11: Commercial vehicle loans from banks/NBFCs typically 9.5–12%; mid-point used.
A12: Insurance, % of ex-showroom per year | B12: 0.03 | C12: %/yr | D12: Team assumption | E12: Commercial comprehensive cover for a ₹10–12 L vehicle; applied flat over 5 years (conservative).
A13: Residual value – Ertiga CNG at yr 5 | B13: 0.15 | C13: % of price | D13: Team assumption | E13: High-mileage taxi (3–4 lakh km) resale; slide 2 uses a 15–20% range.
A14: Residual value – Tour-e bought outright | B14: 0.15 | C14: % of price | D14: Team assumption | E14: Same as CNG – no EV premium assumed despite SoH passport (conservative).
A15: Residual value – Tour-e body under BaaS | B15: 0.2 | C15: % of price | D15: Team assumption | E15: Battery stays with the BaaS provider, so the buyer holds no pack-fade risk; body/eAxle retain value better.
A16: 2 · Tour-e energy (design targets)
A17: Usable battery capacity | B17: 45 | C17: kWh | D17: Design target | E17: Sized to cover a 200–250 km duty day with margin on one overnight charge.
A18: Gross battery capacity | B18: 48 | C18: kWh | D18: Design target | E18: ≈94% usable window, typical for LFP packs.
A19: Energy use at the battery (real-world, AC on) | B19: 0.15 | C19: kWh/km | D19: Design target | E19: Compact MPV, ~1.6 t, heavy AC use; e VITARA-class vehicles achieve 130–160 Wh/km. 45 kWh ÷ 0.150 = 300 km.
A20: Charging efficiency (grid → battery) | B20: 0.9 | C20: % | D20: Team assumption | E20: AC/DC charging losses of ~10%.
A21: Depot / overnight tariff | B21: 9 | C21: ₹/kWh | D21: Team assumption | E21: State commercial / EV-specific tariffs are typically ₹7–10/kWh incl. fixed charges (e.g., state EV tariff orders); ₹9 used.
A22: Public DC fast-charging tariff | B22: 20 | C22: ₹/kWh | D22: Sourced (range) | E22: Public DC CPO pricing in India 2026 is ~₹18–25/kWh incl. GST (MeraEV / MyMotor tariff guides).
A23: Share of energy charged at depot | B23: 0.8 | C23: % | D23: Team assumption | E23: Fleet model built around overnight depot charging; 20% top-ups at public DC.
A24: Tour-e maintenance + tyres | B24: 0.55 | C24: ₹/km | D24: Team assumption | E24: No engine oil, filters, clutch; regen reduces brake wear. ~40–45% lower than CNG, consistent with fleet-operator reports.
A25: 3 · Ertiga Tour M CNG benchmark
A26: Ertiga Tour M CNG ex-showroom (post GST 2.0) | B26: 10.745 | C26: ₹ lakh | D26: Sourced | E26: ₹10.74 L – Maruti post-GST 2.0 price list via Autocar India; Tour M is the fleet version of India's No.1 MPV.
A27: CNG price | B27: 85 | C27: ₹/kg | D27: Sourced (rounded down) | E27: Delhi IGL ₹86.98/kg from 29 Aug 2026 (Outlook Business, Goodreturns). ₹85 is slightly conservative – it favours CNG.
A28: CNG real-world efficiency | B28: 20 | C28: km/kg | D28: Team assumption | E28: Claimed 26.11 km/kg (ARAI); city taxi duty with AC typically 18–21 km/kg.
A29: CNG maintenance + tyres | B29: 0.95 | C29: ₹/km | D29: Team assumption | E29: Engine oil/filter every 10k km, spark plugs, clutch, CNG kit servicing and hydro-testing.
A30: 4 · Cost stack & pricing
A31: Battery pack cost 2028 (landed, pack level) | B31: 8000 | C31: ₹/kWh | D31: Sourced (anchored) | E31: ≈$84/kWh × ₹95/$ – BNEF 2025 survey: China average pack price $84/kWh (global $108). Cross-check: e VITARA 49 kWh pack priced ~₹5 L retail.
A32: Battery pack cost 2035 | B32: 6500 | C32: ₹/kWh | D32: Team assumption | E32: ~19% below 2028 in real terms (≈3%/yr) via localised cells (ACC-PLI) and LFP scale; conservative vs. BNEF outlooks.
A33: Exchange rate | B33: 95 | C33: ₹/US$ | D33: Sourced | E33: INR traded ~₹94.6–95.4 per US$ in Jun–Aug 2026 (HDFC Sky daily market reports).
A34: OEM margin on cost | B34: 0.08 | C34: % | D34: Team assumption | E34: Mass-market OEM EBIT margins ~7–10%.
A35: Dealer margin | B35: 0.04 | C35: % | D35: Team assumption | E35: Fleet sales carry thin dealer margins (3–5%).
A36: GST on EVs | B36: 0.05 | C36: % | D36: Sourced | E36: GST Council, GST 2.0 effective 22 Sep 2025: EVs stay at 5%.
A37: GST on CNG cars >4 m (for reference) | B37: 0.4 | C37: % | D37: Sourced | E37: GST 2.0: petrol/CNG cars >4 m or >1,200 cc attract 40% (Ertiga included).
A38: 5 · Battery-as-a-Service (BaaS)
A39: BaaS provider cost of capital | B39: 0.11 | C39: % | D39: Team assumption | E39: NBFC/lessor funding cost for battery assets.
A40: BaaS amortisation term | B40: 5 | C40: years | D40: Team assumption | E40: Matches the fleet holding period.
A41: Pack residual value at end of term | B41: 0.25 | C41: % of pack price | D41: Team assumption | E41: LFP pack at ≥70% SoH has second-life value (stationary storage).
...

Sheet Cost_Price
A1: Bottom-up cost stack & price build-up (₹ lakh per vehicle, 2026 ₹)
A2: Team estimate for a HEARTECT-e derived compact MPV. Battery line is formula-driven; other lines are inputs (blue).
A4: Cost line | B4: 2028 launch | C4: 2035 scale | D4: Change | E4: Basis
A5: Battery pack (48 kWh gross) | B5: =Inputs!$B$18*Inputs!$B$31/100000 -> 3.84 | C5: =Inputs!$B$18*Inputs!$B$32/100000 -> 3.12 | D5: =C5/B5-1 -> -0.1875 | E5: Gross kWh × ₹/kWh (Inputs). 2028 ≈ BNEF China pack average; cross-check e VITARA pack ~₹5 L retail.
A6: Body-in-white, paint, closures (incl. powered sliding door) | B6: 1.35 | C6: 1.25 | D6: =C6/B6-1 -> -0.074074074 | E6: Ertiga-class steel body; one powered kerb-side slider.
A7: Interior & seats (5+2, fold-flat 3rd row) | B7: 0.85 | C7: 0.76 | D7: =C7/B7-1 -> -0.10588235 | E7: Taxi-grade washable trim.
A8: Chassis, suspension, brakes, wheels | B8: 0.7 | C8: 0.64 | D8: =C8/B8-1 -> -0.085714286 | E8: Heavy-duty dampers and bushes for commercial duty.
A9: Low-voltage electrics & harness | B9: 0.45 | C9: 0.38 | D9: =C9/B9-1 -> -0.15555556 | E9: Localised harness.
A10: Safety: 6 airbags, ESP, ADAS-L2, DMS camera | B10: 0.35 | C10: 0.3 | D10: =C10/B10-1 -> -0.14285714 | E10: Camera/radar costs fall with scale.
A11: eAxle (motor + inverter + reducer), reduced rare-earth | B11: 0.7 | C11: 0.55 | D11: =C11/B11-1 -> -0.21428571 | E11: Largest localisation gain by 2035.
A12: HV electronics (OBC, DC-DC, junction box) | B12: 0.4 | C12: 0.3 | D12: =C12/B12-1 -> -0.25 | E12: 11 kW OBC, CCS2 100–120 kW.
A13: Thermal: liquid-cooled pack, heat pump, roof rear AC | B13: 0.4 | C13: 0.34 | D13: =C13/B13-1 -> -0.15 | E13: 'India Heat Pack'.
A14: Telematics / FleetOS hardware | B14: 0.1 | C14: 0.07 | D14: =C14/B14-1 -> -0.3 | E14: 4G/5G TCU, OTA-capable.
A15: Assembly, overhead, logistics | B15: 0.7 | C15: 0.62 | D15: =C15/B15-1 -> -0.11428571 | E15: Shared lines with HEARTECT-e platform.
A16: Warranty provision | B16: 0.3 | C16: 0.25 | D16: =C16/B16-1 -> -0.16666667 | E16: Vehicle warranty (battery risk sits with BaaS).
A17: R&D / tooling amortisation | B17: 0.4 | C17: 0.38 | D17: =C17/B17-1 -> -0.05 | E17: Amortised over platform volume.
A18: Ex-factory cost (total) | B18: =SUM(B5:B17) -> 10.54 | C18: =SUM(C5:C17) -> 8.96 | D18: =C18/B18-1 -> -0.14990512 | E18: Sum of lines.
A19: of which battery share | B19: =B5/B18 -> 0.36432638 | C19: =C5/C18 -> 0.34821429 | D19: =C19/B19-1 -> -0.04422433
A20: Non-battery cost | B20: =B18-B5 -> 6.7 | C20: =C18-C5 -> 5.84 | D20: =C20/B20-1 -> -0.12835821
A22: Price build-up
A23: × OEM margin | B23: =Inputs!$B$34 -> 0.08 | C23: =Inputs!$B$34 -> 0.08 | D23: =C23/B23-1 -> 0 | E23: Inputs
A24: × Dealer margin | B24: =Inputs!$B$35 -> 0.04 | C24: =Inputs!$B$35 -> 0.04 | D24: =C24/B24-1 -> 0 | E24: Inputs
A25: × GST on EVs | B25: =Inputs!$B$36 -> 0.05 | C25: =Inputs!$B$36 -> 0.05 | D25: =C25/B25-1 -> 0 | E25: Inputs
A26: Price multiplier on cost | B26: =(1+Inputs!$B$34)*(1+Inputs!$B$35)*(1+Inputs!$B$36) -> 1.17936 | C26: =(1+Inputs!$B$34)*(1+Inputs!$B$35)*(1+Inputs!$B$36) -> 1.17936 | D26: =C26/B26-1 -> 0 | E26: 1.08 × 1.04 × 1.05
A27: Ex-showroom price, bought outright (₹ L) | B27: =B18*B26 -> 12.430454 | C27: =C18*C26 -> 10.567066 | D27: =C27/B27-1 -> -0.14990512 | E27: Slide 2: ₹12.4 L (2028) → ₹10.6 L (2035).
A28: Fleet BaaS: vehicle-only price (₹ L) | B28: =B20*B26 -> 7.901712 | C28: =C20*C26 -> 6.8874624 | D28: =C28/B28-1 -> -0.12835821 | E28: Battery excluded – owned by BaaS provider. Slide 2: ₹7.9 L → ₹6.9 L.
A29: OEM transfer price of pack to BaaS provider (₹ L) | B29: =B5*(1+Inputs!$B$34) -> 4.1472 | C29: =C5*(1+Inputs!$B$34) -> 3.3696 | D29: =C29/B29-1 -> -0.1875 | E29: Pack sold at cost + OEM margin (no dealer margin / GST in this model).
A30: Pack cost in US$/kWh (check) | B30: =Inputs!$B$31/Inputs!$B$33 -> 84.210526 | C30: =Inputs!$B$32/Inputs!$B$33 -> 68.421053 | D30: =C30/B30-1 -> -0.1875 | E30: BNEF 2025: China avg $84/kWh; LFP avg $81/kWh; global $108/kWh.
A32: Benchmarks (for context)
A33: Ertiga Tour M CNG ex-showroom | B33: =Inputs!$B$26 -> 10.745 | E33: Maruti post-GST price list (Autocar India).
A34: Retail e VITARA – BaaS price / outright | B34: 10.99 / 15.99 | E34: Maruti Suzuki, Feb 2026 (Autocar India, Upstox).
A35: Tour-e 2028 outright premium over Ertiga CNG | B35: =B27-Inputs!$B$26 -> 1.6854544 | E35: Repaid by running-cost savings – see Fleet_Economics.

Sheet BaaS
A1: Fleet Battery-as-a-Service: break-even rate
A2: Provider buys the pack, finances it, keeps residual value and carries fade risk.
A4: Step | B4: 2028 | C4: 2035 | D4: Formula / note
A5: Pack price paid by provider (₹ L) | B5: =Cost_Price!$B$29 -> 4.1472 | C5: =Cost_Price!$C$29 -> 3.3696 | D5: From Cost_Price.
A6: Annual capital recovery net of residual (₹ L/yr) | B6: =PMT(Inputs!$B$39,Inputs!$B$40,-B5,Inputs!$B$41*B5) -> 0.95562989 | C6: =PMT(Inputs!$B$39,Inputs!$B$40,-C5,Inputs!$B$41*C5) -> 0.77644929 | D6: PMT(11%, 5 yrs, pack, 25% residual as future value).
A7: + Risk reserve | B7: =B6*Inputs!$B$42 -> 0.095562989 | C7: =C6*Inputs!$B$42 -> 0.077644929 | D7: 10% of capital recovery.
A8: + Provider margin | B8: =(B6+B7)*Inputs!$B$43 -> 0.08409543 | C8: =(C6+C7)*Inputs!$B$43 -> 0.068327537 | D8: 8% on cost incl. reserve.
A9: Annual revenue required (₹ L/yr) | B9: =B6+B7+B8 -> 1.1352883 | C9: =C6+C7+C8 -> 0.92242175
A10: Break-even at minimum contract km (₹/km) | B10: =B9*100000/Inputs!$B$44 -> 1.8921472 | C10: =C9*100000/Inputs!$B$44 -> 1.5373696 | D10: Slide 2: ₹1.89 (2028) / ₹1.54 (2035).
A11: Break-even at fleet km (₹/km) | B11: =B9*100000/Inputs!$B$8 -> 1.4191104 | C11: =C9*100000/Inputs!$B$8 -> 1.1530272 | D11: Slide 2: ₹1.42 / ₹1.15 – upside for the provider at 80k km.
A12: Chosen fleet BaaS rate (₹/km) | B12: =Inputs!$B$45 -> 2 | C12: =Inputs!$B$46 -> 1.6 | D12: Rounded up above break-even.
A13: Headroom over break-even at minimum km | B13: =B12/B10-1 -> 0.057000226 | C13: =C12/C10-1 -> 0.040738684 | D13: Must be ≥ 0.
A14: Provider annual margin at fleet km after costs (₹ L/yr/car) | B14: =B12*Inputs!$B$8/100000-B6-B7 -> 0.54880712 | C14: =C12*Inputs!$B$8/100000-C6-C7 -> 0.42590579 | D14: Revenue at 80k km minus capital + reserve.
A16: Why the fleet rate is half the retail e VITARA rate
A17: Retail e VITARA BaaS (₹/km) | B17: =Inputs!$B$47 -> 3.99 | D17: Maruti Suzuki, Feb 2026.
A18: Retail usage basis (km/yr) | B18: =Inputs!$B$48 -> 21900 | D18: ~60 km/day.
A19: Fleet minimum km ÷ retail km | B19: =Inputs!$B$44/Inputs!$B$48 -> 2.739726 | D19: Same pack, ~2.7× the km → far lower ₹/km.
A20: Retail rate spread over fleet km (₹/km) | B20: =Inputs!$B$47*Inputs!$B$48/Inputs!$B$44 -> 1.45635 | D20: Pure scaling of the retail rate. The ₹2.0 fleet rate sits above this, so it is conservative for the provider.
A22: Battery duty check
A23: Lifetime km at fleet duty (5 yrs) | B23: =Inputs!$B$8*Inputs!$B$6 -> 400000 | D23: 4 lakh km design life (slide 2).
A24: Energy throughput at battery (kWh) | B24: =B23*Inputs!$B$19 -> 60000
A25: Equivalent full cycles (usable kWh) | B25: =B24/Inputs!$B$17 -> 1333.3333 | D25: ≈1,330–1,450 equivalent full cycles over 5 years – well within LFP cycle life (automotive LFP cells are typically rated 3,000+ cycles).
A26: Real-world range (km) | B26: =Inputs!$B$17/Inputs!$B$19 -> 300 | D26: 45 kWh ÷ 150 Wh/km.
A27: Range at 70% SoH end-of-life (km) | B27: =Inputs!$B$17*0.7/Inputs!$B$19 -> 210 | D27: Still covers a 200 km owner-driver day.

Sheet TCO
A1: 5-year TCO per km – Tour-e vs Ertiga Tour M CNG (2028 launch prices)
A2: Capital = annualised loan cost net of residual (PMT) + insurance. Driver wage excluded. 2026 ₹.
A4: Owner-driver: annual km = | B4: =Inputs!$B$7 -> 60000
A5: OWNER-DRIVER @ 60k km/yr | B5: Ertiga CNG | C5: Tour-e + BaaS | D5: Tour-e outright | E5: How it is calculated
A6: Energy (₹/km) | B6: =ROUND(Inputs!$B$27/Inputs!$B$28,2) -> 4.25 | C6: =ROUND(Inputs!$B$19/Inputs!$B$20*(Inputs!$B$23*Inputs!$B$21+(1-Inputs!$B$23)*Inputs!$B$22),2) -> 1.87 | D6: =ROUND(Inputs!$B$19/Inputs!$B$20*(Inputs!$B$23*Inputs!$B$21+(1-Inputs!$B$23)*Inputs!$B$22),2) -> 1.87 | E6: CNG: ₹/kg ÷ km/kg. EV: kWh/km ÷ charging eff. × blended tariff (80% depot ₹9, 20% DC ₹20 = ₹11.2).
A7: Maintenance & tyres (₹/km) | B7: =Inputs!$B$29 -> 0.95 | C7: =Inputs!$B$24 -> 0.55 | D7: =Inputs!$B$24 -> 0.55 | E7: Inputs.
A8: Battery subscription (₹/km) | B8: =0 -> 0 | C8: =Inputs!$B$45 -> 2 | D8: =0 -> 0 | E8: Fleet BaaS rate, 2028.
A9: Upfront price (₹ lakh) | B9: =Inputs!$B$26 -> 10.745 | C9: =Cost_Price!$B$28 -> 7.901712 | D9: =Cost_Price!$B$27 -> 12.430454 | E9: Ex-showroom; road-tax/permit waivers for EVs excluded (conservative).
A10: Residual at year 5 | B10: =Inputs!$B$13 -> 0.15 | C10: =Inputs!$B$15 -> 0.2 | D10: =Inputs!$B$14 -> 0.15 | E10: Inputs.
A11: Capital: annual loan cost net of residual (₹ L/yr) | B11: =PMT(Inputs!$B$11,Inputs!$B$6,-B9,B10*B9) -> 2.6094143 | C11: =PMT(Inputs!$B$11,Inputs!$B$6,-C9,C10*C9) -> 1.854851 | D11: =PMT(Inputs!$B$11,Inputs!$B$6,-D9,D10*D9) -> 3.0187255 | E11: PMT(10.5%, 5, price, residual).
A12: Insurance (₹ L/yr) | B12: =Inputs!$B$12*B9 -> 0.32235 | C12: =Inputs!$B$12*C9 -> 0.23705136 | D12: =Inputs!$B$12*D9 -> 0.37291363 | E12: 3% of ex-showroom.
A13: Capital & insurance (₹/km) | B13: =ROUND((B11+B12)*100000/Inputs!$B$7,2) -> 4.89 | C13: =ROUND((C11+C12)*100000/Inputs!$B$7,2) -> 3.49 | D13: =ROUND((D11+D12)*100000/Inputs!$B$7,2) -> 5.65 | E13: (Capital + insurance) × 1e5 ÷ annual km. Each ₹/km line is shown to the paisa.
A14: TOTAL COST PER KM (₹/km) | B14: =B6+B7+B8+B13 -> 10.09 | C14: =C6+C7+C8+C13 -> 7.91 | D14: =D6+D7+D8+D13 -> 8.07 | E14: Energy + maintenance + battery + capital & insurance.
A15: Annual cost (₹ lakh/yr) | B15: =B14*Inputs!$B$7/100000 -> 6.054 | C15: =C14*Inputs!$B$7/100000 -> 4.746 | D15: =D14*Inputs!$B$7/100000 -> 4.842 | E15: ₹/km × annual km.
A16: 5-year cost (₹ lakh) | B16: =B15*Inputs!$B$6 -> 30.27 | C16: =C15*Inputs!$B$6 -> 23.73 | D16: =D15*Inputs!$B$6 -> 24.21 | E16: Annual × 5 (undiscounted cash view).
A17: Saving vs CNG (₹/km) | B17: =$B14-B14 -> 0 | C17: =$B14-C14 -> 2.18 | D17: =$B14-D14 -> 2.02
A18: Saving vs CNG (₹ lakh/yr) | B18: =B17*Inputs!$B$7/100000 -> 0 | C18: =C17*Inputs!$B$7/100000 -> 1.308 | D18: =D17*Inputs!$B$7/100000 -> 1.212
A20: Fleet: annual km = | B20: =Inputs!$B$8 -> 80000
A21: FLEET @ 80k km/yr | B21: Ertiga CNG | C21: Tour-e + BaaS | D21: Tour-e outright | E21: How it is calculated
A22: Energy (₹/km) | B22: =ROUND(Inputs!$B$27/Inputs!$B$28,2) -> 4.25 | C22: =ROUND(Inputs!$B$19/Inputs!$B$20*(Inputs!$B$23*Inputs!$B$21+(1-Inputs!$B$23)*Inputs!$B$22),2) -> 1.87 | D22: =ROUND(Inputs!$B$19/Inputs!$B$20*(Inputs!$B$23*Inputs!$B$21+(1-Inputs!$B$23)*Inputs!$B$22),2) -> 1.87 | E22: CNG: ₹/kg ÷ km/kg. EV: kWh/km ÷ charging eff. × blended tariff (80% depot ₹9, 20% DC ₹20 = ₹11.2).
A23: Maintenance & tyres (₹/km) | B23: =Inputs!$B$29 -> 0.95 | C23: =Inputs!$B$24 -> 0.55 | D23: =Inputs!$B$24 -> 0.55 | E23: Inputs.
A24: Battery subscription (₹/km) | B24: =0 -> 0 | C24: =Inputs!$B$45 -> 2 | D24: =0 -> 0 | E24: Fleet BaaS rate, 2028.
A25: Upfront price (₹ lakh) | B25: =Inputs!$B$26 -> 10.745 | C25: =Cost_Price!$B$28 -> 7.901712 | D25: =Cost_Price!$B$27 -> 12.430454 | E25: Ex-showroom; road-tax/permit waivers for EVs excluded (conservative).
A26: Residual at year 5 | B26: =Inputs!$B$13 -> 0.15 | C26: =Inputs!$B$15 -> 0.2 | D26: =Inputs!$B$14 -> 0.15 | E26: Inputs.
A27: Capital: annual loan cost net of residual (₹ L/yr) | B27: =PMT(Inputs!$B$11,Inputs!$B$6,-B25,B26*B25) -> 2.6094143 | C27: =PMT(Inputs!$B$11,Inputs!$B$6,-C25,C26*C25) -> 1.854851 | D27: =PMT(Inputs!$B$11,Inputs!$B$6,-D25,D26*D25) -> 3.0187255 | E27: PMT(10.5%, 5, price, residual).
A28: Insurance (₹ L/yr) | B28: =Inputs!$B$12*B25 -> 0.32235 | C28: =Inputs!$B$12*C25 -> 0.23705136 | D28: =Inputs!$B$12*D25 -> 0.37291363 | E28: 3% of ex-showroom.
A29: Capital & insurance (₹/km) | B29: =ROUND((B27+B28)*100000/Inputs!$B$8,2) -> 3.66 | C29: =ROUND((C27+C28)*100000/Inputs!$B$8,2) -> 2.61 | D29: =ROUND((D27+D28)*100000/Inputs!$B$8,2) -> 4.24 | E29: (Capital + insurance) × 1e5 ÷ annual km. Each ₹/km line is shown to the paisa.
A30: TOTAL COST PER KM (₹/km) | B30: =B22+B23+B24+B29 -> 8.86 | C30: =C22+C23+C24+C29 -> 7.03 | D30: =D22+D23+D24+D29 -> 6.66 | E30: Energy + maintenance + battery + capital & insurance.
A31: Annual cost (₹ lakh/yr) | B31: =B30*Inputs!$B$8/100000 -> 7.088 | C31: =C30*Inputs!$B$8/100000 -> 5.624 | D31: =D30*Inputs!$B$8/100000 -> 5.328 | E31: ₹/km × annual km.
A32: 5-year cost (₹ lakh) | B32: =B31*Inputs!$B$6 -> 35.44 | C32: =C31*Inputs!$B$6 -> 28.12 | D32: =D31*Inputs!$B$6 -> 26.64 | E32: Annual × 5 (undiscounted cash view).
A33: Saving vs CNG (₹/km) | B33: =$B30-B30 -> 0 | C33: =$B30-C30 -> 1.83 | D33: =$B30-D30 -> 2.2
A34: Saving vs CNG (₹ lakh/yr) | B34: =B33*Inputs!$B$8/100000 -> 0 | C34: =C33*Inputs!$B$8/100000 -> 1.464 | D34: =D33*Inputs!$B$8/100000 -> 1.76
A37: Ties to the 2-slide deck
A38: • Tour-e + BaaS: energy 1.87 + maintenance 0.55 + battery 2.00 + capital & insurance 3.49 = ₹7.91/km.
A39: • Ertiga Tour M CNG: energy 4.25 + maintenance 0.95 + capital & insurance 4.89 = ₹10.09/km. Tour-e bought outright: ₹8.07/km.
A40: • Owner-driver uplift = (10.09 − 7.91) × 5,000 km = ₹10.9k per month.

Sheet Driver_Economics
A1: Owner-driver economics (monthly)
A2: Uplift = CNG ₹/km − Tour-e ₹/km × monthly km. It does not depend on the fare assumption.
A4: Item | B4: Ertiga CNG | C4: Tour-e + BaaS | D4: Tour-e outright | E4: Note
A5: Monthly km | B5: =Inputs!$B$7/12 -> 5000 | C5: =Inputs!$B$7/12 -> 5000 | D5: =Inputs!$B$7/12 -> 5000 | E5: 60,000 ÷ 12 = 5,000 km.
A6: Average daily km | B6: =Inputs!$B$7/Inputs!$B$9 -> 200 | C6: =Inputs!$B$7/Inputs!$B$9 -> 200 | D6: =Inputs!$B$7/Inputs!$B$9 -> 200 | E6: vs ~300 km real range → one overnight charge per day.
A7: Vehicle cost per km (₹/km) | B7: =TCO!B14 -> 10.09 | C7: =TCO!C14 -> 7.91 | D7: =TCO!D14 -> 8.07 | E7: From TCO sheet.
A8: Monthly vehicle cost (₹) | B8: =B7*B5 -> 50450 | C8: =C7*C5 -> 39550 | D8: =D7*D5 -> 40350
A9: Net fare earnings (₹/month, illustrative) | B9: =Inputs!$B$50*Inputs!$B$7/12 -> 67500 | C9: =Inputs!$B$50*Inputs!$B$7/12 -> 67500 | D9: =Inputs!$B$50*Inputs!$B$7/12 -> 67500 | E9: ₹13.5/km net of commission × 5,000 km.
A10: Driver take-home after vehicle costs (₹/month) | B10: =B9-B8 -> 17050 | C10: =C9-C8 -> 27950 | D10: =D9-D8 -> 27150 | E10: Illustrative – depends on fare level.
A11: Uplift vs CNG (₹/month) | B11: =$B8-B8 -> 0 | C11: =$B8-C8 -> 10900 | D11: =$B8-D8 -> 10100 | E11: Slide 2: +₹10.9k/month. Independent of fares.
A12: Uplift vs CNG (₹/year) | B12: =B11*12 -> 0 | C12: =C11*12 -> 130800 | D12: =D11*12 -> 121200
A13: Take-home change vs CNG | B13: =B10/$B10-1 -> 0 | C13: =C10/$B10-1 -> 0.63929619 | D13: =D10/$B10-1 -> 0.59237537 | E13: Illustrative.
A14: Upfront outlay difference vs CNG (₹ lakh) | B14: =TCO!B9-TCO!$B9 -> 0 | C14: =TCO!C9-TCO!$B9 -> -2.843288 | D14: =TCO!D9-TCO!$B9 -> 1.6854544 | E14: BaaS lowers upfront price below the CNG car.
A16: Uptime check
A17: Real-world range (km) | B17: =BaaS!$B$26 -> 300
A18: Owner-driver daily km | B18: =B6 -> 200
A19: Range buffer at end of owner-driver day (km) | B19: =B17-B18 -> 100
A20: Fleet daily km | B20: =Inputs!$B$8/Inputs!$B$10 -> 250
A21: Range buffer at end of fleet day (km) | B21: =B17-B20 -> 50
A22: A 200–250 km duty day fits on one overnight depot charge; a ≤30 min DC top-up (10–80%) covers any extra shift.

Sheet Fleet_Economics
A1: Fleet operator economics (per car and per 100-car fleet, 80k km/yr)
A4: Item | B4: Ertiga CNG | C4: Tour-e + BaaS | D4: Tour-e outright | E4: Note
A5: Cost per km (₹/km) | B5: =TCO!B30 -> 8.86 | C5: =TCO!C30 -> 7.03 | D5: =TCO!D30 -> 6.66 | E5: TCO sheet, fleet block.
A6: Annual cost per car (₹ lakh) | B6: =TCO!B31 -> 7.088 | C6: =TCO!C31 -> 5.624 | D6: =TCO!D31 -> 5.328
A7: Annual saving per car vs CNG (₹ lakh) | B7: =TCO!B34 -> 0 | C7: =TCO!C34 -> 1.464 | D7: =TCO!D34 -> 1.76 | E7: Slide 2: ₹1.5 L (BaaS) – ₹1.8 L (outright).
A8: 5-year saving per car vs CNG (₹ lakh) | B8: =B7*Inputs!$B$6 -> 0 | C8: =C7*Inputs!$B$6 -> 7.32 | D8: =D7*Inputs!$B$6 -> 8.8
A9: Upfront capex per car (₹ lakh) | B9: =TCO!B25 -> 10.745 | C9: =TCO!C25 -> 7.901712 | D9: =TCO!D25 -> 12.430454
A10: Extra capex vs CNG (₹ lakh) | B10: =B9-$B9 -> 0 | C10: =C9-$B9 -> -2.843288 | D10: =D9-$B9 -> 1.6854544 | E10: Negative = cheaper upfront.
A11: Running-cost saving vs CNG (energy + maint., ₹ lakh/yr) | B11: =((TCO!$B22+TCO!$B23)-(TCO!B22+TCO!B23+TCO!B24))*Inputs!$B$8/100000 -> 0 | C11: =((TCO!$B22+TCO!$B23)-(TCO!C22+TCO!C23+TCO!C24))*Inputs!$B$8/100000 -> 0.624 | D11: =((TCO!$B22+TCO!$B23)-(TCO!D22+TCO!D23+TCO!D24))*Inputs!$B$8/100000 -> 2.224 | E11: Outright case excludes battery fee.
A12: Simple payback of extra capex (months) | B12: =IF(B10<=0,0,B10/B11*12) -> 0 | C12: =IF(C10<=0,0,C10/C11*12) -> 0 | D12: =IF(D10<=0,0,D10/D11*12) -> 9.0941784 | E12: Slide 2: ~9 months (outright). BaaS: immediate.
A13: Fleet of N cars – annual saving (₹ crore) | B13: =B7*Inputs!$B$51/100 -> 0 | C13: =C7*Inputs!$B$51/100 -> 1.464 | D13: =D7*Inputs!$B$51/100 -> 1.76 | E13: N from Inputs.
A14: Fleet of N cars – capex (₹ crore) | B14: =B9*Inputs!$B$51/100 -> 10.745 | C14: =C9*Inputs!$B$51/100 -> 7.901712 | D14: =D9*Inputs!$B$51/100 -> 12.430454
A16: Reading the payback: BaaS cars cost less upfront than the Ertiga CNG (payback = 0 months); the outright Tour-e costs ₹1.69 L more and repays that in ~9 months from energy + maintenance savings alone.

Sheet Sensitivity
A1: Sensitivity & stress tests (owner-driver unless stated)
A2: Each row recomputes the full ₹/km with one input changed; everything else from Inputs.
A4: A · Annual kilometres
A5: km/yr | B5: CNG ₹/km | C5: Tour-e BaaS ₹/km | D5: Tour-e outright ₹/km | E5: BaaS saving ₹/month | F5: Outright saving ₹/month
A6: 40000 | B6: =(ROUND(Inputs!$B$27/Inputs!$B$28,2)+Inputs!$B$29+ROUND((PMT(Inputs!$B$11,Inputs!$B$6,-Inputs!$B$26,Inputs!$B$13*Inputs!$B$26)+Inputs!$B$12*Inputs!$B$26)*100000/$A6,2)) -> 12.53 | C6: =(ROUND(Inputs!$B$19/Inputs!$B$20*(Inputs!$B$23*Inputs!$B$21+(1-Inputs!$B$23)*Inputs!$B$22),2)+Inputs!$B$24+Inputs!$B$45+ROUND((PMT(Inputs!$B$11,Inputs!$B$6,-Cost_Price!$B$28,Inputs!$B$15*Cost_Price!$B$28)+Inputs!$B$12*Cost_Price!$B$28)*100000/$A6,2)) -> 9.65 | D6: =(ROUND(Inputs!$B$19/Inputs!$B$20*(Inputs!$B$23*Inputs!$B$21+(1-Inputs!$B$23)*Inputs!$B$22),2)+Inputs!$B$24+ROUND((PMT(Inputs!$B$11,Inputs!$B$6,-Cost_Price!$B$27,Inputs!$B$14*Cost_Price!$B$27)+Inputs!$B$12*Cost_Price!$B$27)*100000/$A6,2)) -> 10.9 | E6: =(B6-C6)*$A6/12 -> 9600 | F6: =(B6-D6)*$A6/12 -> 5433.3333
A7: 50000 | B7: =(ROUND(Inputs!$B$27/Inputs!$B$28,2)+Inputs!$B$29+ROUND((PMT(Inputs!$B$11,Inputs!$B$6,-Inputs!$B$26,Inputs!$B$13*Inputs!$B$26)+Inputs!$B$12*Inputs!$B$26)*100000/$A7,2)) -> 11.06 | C7: =(ROUND(Inputs!$B$19/Inputs!$B$20*(Inputs!$B$23*Inputs!$B$21+(1-Inputs!$B$23)*Inputs!$B$22),2)+Inputs!$B$24+Inputs!$B$45+ROUND((PMT(Inputs!$B$11,Inputs!$B$6,-Cost_Price!$B$28,Inputs!$B$15*Cost_Price!$B$28)+Inputs!$B$12*Cost_Price!$B$28)*100000/$A7,2)) -> 8.6 | D7: =(ROUND(Inputs!$B$19/Inputs!$B$20*(Inputs!$B$23*Inputs!$B$21+(1-Inputs!$B$23)*Inputs!$B$22),2)+Inputs!$B$24+ROUND((PMT(Inputs!$B$11,Inputs!$B$6,-Cost_Price!$B$27,Inputs!$B$14*Cost_Price!$B$27)+Inputs!$B$12*Cost_Price!$B$27)*100000/$A7,2)) -> 9.2 | E7: =(B7-C7)*$A7/12 -> 10250 | F7: =(B7-D7)*$A7/12 -> 7750
A8: 60000 | B8: =(ROUND(Inputs!$B$27/Inputs!$B$28,2)+Inputs!$B$29+ROUND((PMT(Inputs!$B$11,Inputs!$B$6,-Inputs!$B$26,Inputs!$B$13*Inputs!$B$26)+Inputs!$B$12*Inputs!$B$26)*100000/$A8,2)) -> 10.09 | C8: =(ROUND(Inputs!$B$19/Inputs!$B$20*(Inputs!$B$23*Inputs!$B$21+(1-Inputs!$B$23)*Inputs!$B$22),2)+Inputs!$B$24+Inputs!$B$45+ROUND((PMT(Inputs!$B$11,Inputs!$B$6,-Cost_Price!$B$28,Inputs!$B$15*Cost_Price!$B$28)+Inputs!$B$12*Cost_Price!$B$28)*100000/$A8,2)) -> 7.91 | D8: =(ROUND(Inputs!$B$19/Inputs!$B$20*(Inputs!$B$23*Inputs!$B$21+(1-Inputs!$B$23)*Inputs!$B$22),2)+Inputs!$B$24+ROUND((PMT(Inputs!$B$11,Inputs!$B$6,-Cost_Price!$B$27,Inputs!$B$14*Cost_Price!$B$27)+Inputs!$B$12*Cost_Price!$B$27)*100000/$A8,2)) -> 8.07 | E8: =(B8-C8)*$A8/12 -> 10900 | F8: =(B8-D8)*$A8/12 -> 10100
A9: 70000 | B9: =(ROUND(Inputs!$B$27/Inputs!$B$28,2)+Inputs!$B$29+ROUND((PMT(Inputs!$B$11,Inputs!$B$6,-Inputs!$B$26,Inputs!$B$13*Inputs!$B$26)+Inputs!$B$12*Inputs!$B$26)*100000/$A9,2)) -> 9.39 | C9: =(ROUND(Inputs!$B$19/Inputs!$B$20*(Inputs!$B$23*Inputs!$B$21+(1-Inputs!$B$23)*Inputs!$B$22),2)+Inputs!$B$24+Inputs!$B$45+ROUND((PMT(Inputs!$B$11,Inputs!$B$6,-Cost_Price!$B$28,Inputs!$B$15*Cost_Price!$B$28)+Inputs!$B$12*Cost_Price!$B$28)*100000/$A9,2)) -> 7.41 | D9: =(ROUND(Inputs!$B$19/Inputs!$B$20*(Inputs!$B$23*Inputs!$B$21+(1-Inputs!$B$23)*Inputs!$B$22),2)+Inputs!$B$24+ROUND((PMT(Inputs!$B$11,Inputs!$B$6,-Cost_Price!$B$27,Inputs!$B$14*Cost_Price!$B$27)+Inputs!$B$12*Cost_Price!$B$27)*100000/$A9,2)) -> 7.27 | E9: =(B9-C9)*$A9/12 -> 11550 | F9: =(B9-D9)*$A9/12 -> 12366.667
A10: 80000 | B10: =(ROUND(Inputs!$B$27/Inputs!$B$28,2)+Inputs!$B$29+ROUND((PMT(Inputs!$B$11,Inputs!$B$6,-Inputs!$B$26,Inputs!$B$13*Inputs!$B$26)+Inputs!$B$12*Inputs!$B$26)*100000/$A10,2)) -> 8.86 | C10: =(ROUND(Inputs!$B$19/Inputs!$B$20*(Inputs!$B$23*Inputs!$B$21+(1-Inputs!$B$23)*Inputs!$B$22),2)+Inputs!$B$24+Inputs!$B$45+ROUND((PMT(Inputs!$B$11,Inputs!$B$6,-Cost_Price!$B$28,Inputs!$B$15*Cost_Price!$B$28)+Inputs!$B$12*Cost_Price!$B$28)*100000/$A10,2)) -> 7.03 | D10: =(ROUND(Inputs!$B$19/Inputs!$B$20*(Inputs!$B$23*Inputs!$B$21+(1-Inputs!$B$23)*Inputs!$B$22),2)+Inputs!$B$24+ROUND((PMT(Inputs!$B$11,Inputs!$B$6,-Cost_Price!$B$27,Inputs!$B$14*Cost_Price!$B$27)+Inputs!$B$12*Cost_Price!$B$27)*100000/$A10,2)) -> 6.66 | E10: =(B10-C10)*$A10/12 -> 12200 | F10: =(B10-D10)*$A10/12 -> 14666.667
A11: 100000 | B11: =(ROUND(Inputs!$B$27/Inputs!$B$28,2)+Inputs!$B$29+ROUND((PMT(Inputs!$B$11,Inputs!$B$6,-Inputs!$B$26,Inputs!$B$13*Inputs!$B$26)+Inputs!$B$12*Inputs!$B$26)*100000/$A11,2)) -> 8.13 | C11: =(ROUND(Inputs!$B$19/Inputs!$B$20*(Inputs!$B$23*Inputs!$B$21+(1-Inputs!$B$23)*Inputs!$B$22),2)+Inputs!$B$24+Inputs!$B$45+ROUND((PMT(Inputs!$B$11,Inputs!$B$6,-Cost_Price!$B$28,Inputs!$B$15*Cost_Price!$B$28)+Inputs!$B$12*Cost_Price!$B$28)*100000/$A11,2)) -> 6.51 | D11: =(ROUND(Inputs!$B$19/Inputs!$B$20*(Inputs!$B$23*Inputs!$B$21+(1-Inputs!$B$23)*Inputs!$B$22),2)+Inputs!$B$24+ROUND((PMT(Inputs!$B$11,Inputs!$B$6,-Cost_Price!$B$27,Inputs!$B$14*Cost_Price!$B$27)+Inputs!$B$12*Cost_Price!$B$27)*100000/$A11,2)) -> 5.81 | E11: =(B11-C11)*$A11/12 -> 13500 | F11: =(B11-D11)*$A11/12 -> 19333.333
A12: Tour-e is cheaper than CNG at every utilisation tested (40k–100k km/yr), and the gap widens with km.
A14: B · CNG price (₹/kg)
A15: ₹/kg | B15: CNG ₹/km | C15: Tour-e BaaS ₹/km | D15: Uplift ₹/month
A16: 65 | B16: =(ROUND($A16/Inputs!$B$28,2)+Inputs!$B$29+ROUND((PMT(Inputs!$B$11,Inputs!$B$6,-Inputs!$B$26,Inputs!$B$13*Inputs!$B$26)+Inputs!$B$12*Inputs!$B$26)*100000/Inputs!$B$7,2)) -> 9.09 | C16: =(ROUND(Inputs!$B$19/Inputs!$B$20*(Inputs!$B$23*Inputs!$B$21+(1-Inputs!$B$23)*Inputs!$B$22),2)+Inputs!$B$24+Inputs!$B$45+ROUND((PMT(Inputs!$B$11,Inputs!$B$6,-Cost_Price!$B$28,Inputs!$B$15*Cost_Price!$B$28)+Inputs!$B$12*Cost_Price!$B$28)*100000/Inputs!$B$7,2)) -> 7.91 | D16: =(B16-C16)*Inputs!$B$7/12 -> 5900
A17: 75 | B17: =(ROUND($A17/Inputs!$B$28,2)+Inputs!$B$29+ROUND((PMT(Inputs!$B$11,Inputs!$B$6,-Inputs!$B$26,Inputs!$B$13*Inputs!$B$26)+Inputs!$B$12*Inputs!$B$26)*100000/Inputs!$B$7,2)) -> 9.59 | C17: =(ROUND(Inputs!$B$19/Inputs!$B$20*(Inputs!$B$23*Inputs!$B$21+(1-Inputs!$B$23)*Inputs!$B$22),2)+Inputs!$B$24+Inputs!$B$45+ROUND((PMT(Inputs!$B$11,Inputs!$B$6,-Cost_Price!$B$28,Inputs!$B$15*Cost_Price!$B$28)+Inputs!$B$12*Cost_Price!$B$28)*100000/Inputs!$B$7,2)) -> 7.91 | D17: =(B17-C17)*Inputs!$B$7/12 -> 8400
A18: 85 | B18: =(ROUND($A18/Inputs!$B$28,2)+Inputs!$B$29+ROUND((PMT(Inputs!$B$11,Inputs!$B$6,-Inputs!$B$26,Inputs!$B$13*Inputs!$B$26)+Inputs!$B$12*Inputs!$B$26)*100000/Inputs!$B$7,2)) -> 10.09 | C18: =(ROUND(Inputs!$B$19/Inputs!$B$20*(Inputs!$B$23*Inputs!$B$21+(1-Inputs!$B$23)*Inputs!$B$22),2)+Inputs!$B$24+Inputs!$B$45+ROUND((PMT(Inputs!$B$11,Inputs!$B$6,-Cost_Price!$B$28,Inputs!$B$15*Cost_Price!$B$28)+Inputs!$B$12*Cost_Price!$B$28)*100000/Inputs!$B$7,2)) -> 7.91 | D18: =(B18-C18)*Inputs!$B$7/12 -> 10900
A19: 95 | B19: =(ROUND($A19/Inputs!$B$28,2)+Inputs!$B$29+ROUND((PMT(Inputs!$B$11,Inputs!$B$6,-Inputs!$B$26,Inputs!$B$13*Inputs!$B$26)+Inputs!$B$12*Inputs!$B$26)*100000/Inputs!$B$7,2)) -> 10.59 | C19: =(ROUND(Inputs!$B$19/Inputs!$B$20*(Inputs!$B$23*Inputs!$B$21+(1-Inputs!$B$23)*Inputs!$B$22),2)+Inputs!$B$24+Inputs!$B$45+ROUND((PMT(Inputs!$B$11,Inputs!$B$6,-Cost_Price!$B$28,Inputs!$B$15*Cost_Price!$B$28)+Inputs!$B$12*Cost_Price!$B$28)*100000/Inputs!$B$7,2)) -> 7.91 | D19: =(B19-C19)*Inputs!$B$7/12 -> 13400
A20: 105 | B20: =(ROUND($A20/Inputs!$B$28,2)+Inputs!$B$29+ROUND((PMT(Inputs!$B$11,Inputs!$B$6,-Inputs!$B$26,Inputs!$B$13*Inputs!$B$26)+Inputs!$B$12*Inputs!$B$26)*100000/Inputs!$B$7,2)) -> 11.09 | C20: =(ROUND(Inputs!$B$19/Inputs!$B$20*(Inputs!$B$23*Inputs!$B$21+(1-Inputs!$B$23)*Inputs!$B$22),2)+Inputs!$B$24+Inputs!$B$45+ROUND((PMT(Inputs!$B$11,Inputs!$B$6,-Cost_Price!$B$28,Inputs!$B$15*Cost_Price!$B$28)+Inputs!$B$12*Cost_Price!$B$28)*100000/Inputs!$B$7,2)) -> 7.91 | D20: =(B20-C20)*Inputs!$B$7/12 -> 15900
A21: Even if CNG falls to ₹75/kg, Tour-e keeps the owner-driver ~₹8.4k/month ahead (slide 2 stress test).
A23: C · Share of energy from public DC
A24: DC share | B24: Blended ₹/kWh | C24: Tour-e BaaS ₹/km | D24: CNG ₹/km | E24: Uplift ₹/month
A25: 0 | B25: =((1-$A25)*Inputs!$B$21+$A25*Inputs!$B$22) -> 9 | C25: =((Inputs!$B$19/Inputs!$B$20*((1-$A25)*Inputs!$B$21+(1-(1-$A25))*Inputs!$B$22))+Inputs!$B$24+Inputs!$B$45+((PMT(Inputs!$B$11,Inputs!$B$6,-Cost_Price!$B$28,Inputs!$B$15*Cost_Price!$B$28)+Inputs!$B$12*Cost_Price!$B$28)*100000/Inputs!$B$7)) -> 7.5365039 | D25: =(ROUND(Inputs!$B$27/Inputs!$B$28,2)+Inputs!$B$29+ROUND((PMT(Inputs!$B$11,Inputs!$B$6,-Inputs!$B$26,Inputs!$B$13*Inputs!$B$26)+Inputs!$B$12*Inputs!$B$26)*100000/Inputs!$B$7,2)) -> 10.09 | E25: =(D25-C25)*Inputs!$B$7/12 -> 12767.48
A26: 0.35 | B26: =((1-$A26)*Inputs!$B$21+$A26*Inputs!$B$22) -> 12.85 | C26: =((Inputs!$B$19/Inputs!$B$20*((1-$A26)*Inputs!$B$21+(1-(1-$A26))*Inputs!$B$22))+Inputs!$B$24+Inputs!$B$45+((PMT(Inputs!$B$11,Inputs!$B$6,-Cost_Price!$B$28,Inputs!$B$15*Cost_Price!$B$28)+Inputs!$B$12*Cost_Price!$B$28)*100000/Inputs!$B$7)) -> 8.1781706 | D26: =(ROUND(Inputs!$B$27/Inputs!$B$28,2)+Inputs!$B$29+ROUND((PMT(Inputs!$B$11,Inputs!$B$6,-Inputs!$B$26,Inputs!$B$13*Inputs!$B$26)+Inputs!$B$12*Inputs!$B$26)*100000/Inputs!$B$7,2)) -> 10.09 | E26: =(D26-C26)*Inputs!$B$7/12 -> 9559.1469
A27: 0.5 | B27: =((1-$A27)*Inputs!$B$21+$A27*Inputs!$B$22) -> 14.5 | C27: =((Inputs!$B$19/Inputs!$B$20*((1-$A27)*Inputs!$B$21+(1-(1-$A27))*Inputs!$B$22))+Inputs!$B$24+Inputs!$B$45+((PMT(Inputs!$B$11,Inputs!$B$6,-Cost_Price!$B$28,Inputs!$B$15*Cost_Price!$B$28)+Inputs!$B$12*Cost_Price!$B$28)*100000/Inputs!$B$7)) -> 8.4531706 | D27: =(ROUND(Inputs!$B$27/Inputs!$B$28,2)+Inputs!$B$29+ROUND((PMT(Inputs!$B$11,Inputs!$B$6,-Inputs!$B$26,Inputs!$B$13*Inputs!$B$26)+Inputs!$B$12*Inputs!$B$26)*100000/Inputs!$B$7,2)) -> 10.09 | E27: =(D27-C27)*Inputs!$B$7/12 -> 8184.1469
A28: 0.75 | B28: =((1-$A28)*Inputs!$B$21+$A28*Inputs!$B$22) -> 17.25 | C28: =((Inputs!$B$19/Inputs!$B$20*((1-$A28)*Inputs!$B$21+(1-(1-$A28))*Inputs!$B$22))+Inputs!$B$24+Inputs!$B$45+((PMT(Inputs!$B$11,Inputs!$B$6,-Cost_Price!$B$28,Inputs!$B$15*Cost_Price!$B$28)+Inputs!$B$12*Cost_Price!$B$28)*100000/Inputs!$B$7)) -> 8.9115039 | D28: =(ROUND(Inputs!$B$27/Inputs!$B$28,2)+Inputs!$B$29+ROUND((PMT(Inputs!$B$11,Inputs!$B$6,-Inputs!$B$26,Inputs!$B$13*Inputs!$B$26)+Inputs!$B$12*Inputs!$B$26)*100000/Inputs!$B$7,2)) -> 10.09 | E28: =(D28-C28)*Inputs!$B$7/12 -> 5892.4803
A29: 1 | B29: =((1-$A29)*Inputs!$B$21+$A29*Inputs!$B$22) -> 20 | C29: =((Inputs!$B$19/Inputs!$B$20*((1-$A29)*Inputs!$B$21+(1-(1-$A29))*Inputs!$B$22))+Inputs!$B$24+Inputs!$B$45+((PMT(Inputs!$B$11,Inputs!$B$6,-Cost_Price!$B$28,Inputs!$B$15*Cost_Price!$B$28)+Inputs!$B$12*Cost_Price!$B$28)*100000/Inputs!$B$7)) -> 9.3698373 | D29: =(ROUND(Inputs!$B$27/Inputs!$B$28,2)+Inputs!$B$29+ROUND((PMT(Inputs!$B$11,Inputs!$B$6,-Inputs!$B$26,Inputs!$B$13*Inputs!$B$26)+Inputs!$B$12*Inputs!$B$26)*100000/Inputs!$B$7,2)) -> 10.09 | E29: =(D29-C29)*Inputs!$B$7/12 -> 3600.8136
A30: 50% public DC charging → ₹8.45/km (slide 2 stress test). Even 100% public DC stays below CNG.
A32: D · Fleet BaaS rate (₹/km)
A33: ₹/km | B33: Tour-e BaaS ₹/km | C33: CNG ₹/km | D33: Uplift ₹/month
A34: 1.6 | B34: =(ROUND(Inputs!$B$19/Inputs!$B$20*(Inputs!$B$23*Inputs!$B$21+(1-Inputs!$B$23)*Inputs!$B$22),2)+Inputs!$B$24+$A34+ROUND((PMT(Inputs!$B$11,Inputs!$B$6,-Cost_Price!$B$28,Inputs!$B$15*Cost_Price!$B$28)+Inputs!$B$12*Cost_Price!$B$28)*100000/Inputs!$B$7,2)) -> 7.51 | C34: =(ROUND(Inputs!$B$27/Inputs!$B$28,2)+Inputs!$B$29+ROUND((PMT(Inputs!$B$11,Inputs!$B$6,-Inputs!$B$26,Inputs!$B$13*Inputs!$B$26)+Inputs!$B$12*Inputs!$B$26)*100000/Inputs!$B$7,2)) -> 10.09 | D34: =(C34-B34)*Inputs!$B$7/12 -> 12900
A35: 1.8 | B35: =(ROUND(Inputs!$B$19/Inputs!$B$20*(Inputs!$B$23*Inputs!$B$21+(1-Inputs!$B$23)*Inputs!$B$22),2)+Inputs!$B$24+$A35+ROUND((PMT(Inputs!$B$11,Inputs!$B$6,-Cost_Price!$B$28,Inputs!$B$15*Cost_Price!$B$28)+Inputs!$B$12*Cost_Price!$B$28)*100000/Inputs!$B$7,2)) -> 7.71 | C35: =(ROUND(Inputs!$B$27/Inputs!$B$28,2)+Inputs!$B$29+ROUND((PMT(Inputs!$B$11,Inputs!$B$6,-Inputs!$B$26,Inputs!$B$13*Inputs!$B$26)+Inputs!$B$12*Inputs!$B$26)*100000/Inputs!$B$7,2)) -> 10.09 | D35: =(C35-B35)*Inputs!$B$7/12 -> 11900
A36: 2 | B36: =(ROUND(Inputs!$B$19/Inputs!$B$20*(Inputs!$B$23*Inputs!$B$21+(1-Inputs!$B$23)*Inputs!$B$22),2)+Inputs!$B$24+$A36+ROUND((PMT(Inputs!$B$11,Inputs!$B$6,-Cost_Price!$B$28,Inputs!$B$15*Cost_Price!$B$28)+Inputs!$B$12*Cost_Price!$B$28)*100000/Inputs!$B$7,2)) -> 7.91 | C36: =(ROUND(Inputs!$B$27/Inputs!$B$28,2)+Inputs!$B$29+ROUND((PMT(Inputs!$B$11,Inputs!$B$6,-Inputs!$B$26,Inputs!$B$13*Inputs!$B$26)+Inputs!$B$12*Inputs!$B$26)*100000/Inputs!$B$7,2)) -> 10.09 | D36: =(C36-B36)*Inputs!$B$7/12 -> 10900
A37: 2.5 | B37: =(ROUND(Inputs!$B$19/Inputs!$B$20*(Inputs!$B$23*Inputs!$B$21+(1-Inputs!$B$23)*Inputs!$B$22),2)+Inputs!$B$24+$A37+ROUND((PMT(Inputs!$B$11,Inputs!$B$6,-Cost_Price!$B$28,Inputs!$B$15*Cost_Price!$B$28)+Inputs!$B$12*Cost_Price!$B$28)*100000/Inputs!$B$7,2)) -> 8.41 | C37: =(ROUND(Inputs!$B$27/Inputs!$B$28,2)+Inputs!$B$29+ROUND((PMT(Inputs!$B$11,Inputs!$B$6,-Inputs!$B$26,Inputs!$B$13*Inputs!$B$26)+Inputs!$B$12*Inputs!$B$26)*100000/Inputs!$B$7,2)) -> 10.09 | D37: =(C37-B37)*Inputs!$B$7/12 -> 8400
A38: 3 | B38: =(ROUND(Inputs!$B$19/Inputs!$B$20*(Inputs!$B$23*Inputs!$B$21+(1-Inputs!$B$23)*Inputs!$B$22),2)+Inputs!$B$24+$A38+ROUND((PMT(Inputs!$B$11,Inputs!$B$6,-Cost_Price!$B$28,Inputs!$B$15*Cost_Price!$B$28)+Inputs!$B$12*Cost_Price!$B$28)*100000/Inputs!$B$7,2)) -> 8.91 | C38: =(ROUND(Inputs!$B$27/Inputs!$B$28,2)+Inputs!$B$29+ROUND((PMT(Inputs!$B$11,Inputs!$B$6,-Inputs!$B$26,Inputs!$B$13*Inputs!$B$26)+Inputs!$B$12*Inputs!$B$26)*100000/Inputs!$B$7,2)) -> 10.09 | D38: =(C38-B38)*Inputs!$B$7/12 -> 5900
A39: 3.99 | B39: =(ROUND(Inputs!$B$19/Inputs!$B$20*(Inputs!$B$23*Inputs!$B$21+(1-Inputs!$B$23)*Inputs!$B$22),2)+Inputs!$B$24+$A39+ROUND((PMT(Inputs!$B$11,Inputs!$B$6,-Cost_Price!$B$28,Inputs!$B$15*Cost_Price!$B$28)+Inputs!$B$12*Cost_Price!$B$28)*100000/Inputs!$B$7,2)) -> 9.9 | C39: =(ROUND(Inputs!$B$27/Inputs!$B$28,2)+Inputs!$B$29+ROUND((PMT(Inputs!$B$11,Inputs!$B$6,-Inputs!$B$26,Inputs!$B$13*Inputs!$B$26)+Inputs!$B$12*Inputs!$B$26)*100000/Inputs!$B$7,2)) -> 10.09 | D39: =(C39-B39)*Inputs!$B$7/12 -> 950
A40: Tour-e stays ahead of CNG up to a battery rate of ₹4.18/km (break-even G), above even the retail e VITARA rate.
A42: E · Real-world energy use (kWh/km)
A43: kWh/km | B43: Range on 45 kWh (km) | C43: Tour-e BaaS ₹/km | D43: Uplift ₹/month
A44: 0.13 | B44: =Inputs!$B$17/$A44 -> 346.15385 | C44: =(ROUND($A44/Inputs!$B$20*(Inputs!$B$23*Inputs!$B$21+(1-Inputs!$B$23)*Inputs!$B$22),2)+Inputs!$B$24+Inputs!$B$45+ROUND((PMT(Inputs!$B$11,Inputs!$B$6,-Cost_Price!$B$28,Inputs!$B$15*Cost_Price!$B$28)+Inputs!$B$12*Cost_Price!$B$28)*100000/Inputs!$B$7,2)) -> 7.66 | D44: =((ROUND(Inputs!$B$27/Inputs!$B$28,2)+Inputs!$B$29+ROUND((PMT(Inputs!$B$11,Inputs!$B$6,-Inputs!$B$26,Inputs!$B$13*Inputs!$B$26)+Inputs!$B$12*Inputs!$B$26)*100000/Inputs!$B$7,2))-C44)*Inputs!$B$7/12 -> 12150
A45: 0.15 | B45: =Inputs!$B$17/$A45 -> 300 | C45: =(ROUND($A45/Inputs!$B$20*(Inputs!$B$23*Inputs!$B$21+(1-Inputs!$B$23)*Inputs!$B$22),2)+Inputs!$B$24+Inputs!$B$45+ROUND((PMT(Inputs!$B$11,Inputs!$B$6,-Cost_Price!$B$28,Inputs!$B$15*Cost_Price!$B$28)+Inputs!$B$12*Cost_Price!$B$28)*100000/Inputs!$B$7,2)) -> 7.91 | D45: =((ROUND(Inputs!$B$27/Inputs!$B$28,2)+Inputs!$B$29+ROUND((PMT(Inputs!$B$11,Inputs!$B$6,-Inputs!$B$26,Inputs!$B$13*Inputs!$B$26)+Inputs!$B$12*Inputs!$B$26)*100000/Inputs!$B$7,2))-C45)*Inputs!$B$7/12 -> 10900
...

Sheet Scenario_2035
A1: 2035 at scale – same duty cycle, 2035 prices (2026 ₹)
A2: Energy, CNG and maintenance held at 2026 levels; only vehicle price and BaaS rate change.
A4: Item (60k km/yr) | B4: Ertiga CNG | C4: Tour-e + BaaS 2035 | D4: Tour-e outright 2035 | E4: Note
A5: Energy (₹/km) | B5: =TCO!B6 -> 4.25 | C5: =TCO!C6 -> 1.87 | D5: =TCO!D6 -> 1.87
A6: Maintenance (₹/km) | B6: =TCO!B7 -> 0.95 | C6: =TCO!C7 -> 0.55 | D6: =TCO!D7 -> 0.55
A7: Battery subscription (₹/km) | B7: =0 -> 0 | C7: =Inputs!$B$46 -> 1.6 | D7: =0 -> 0
A8: Upfront price (₹ lakh) | B8: =Inputs!$B$26 -> 10.745 | C8: =Cost_Price!$C$28 -> 6.8874624 | D8: =Cost_Price!$C$27 -> 10.567066
A9: Capital & insurance (₹/km) | B9: =ROUND((PMT(Inputs!$B$11,Inputs!$B$6,-B8,Inputs!$B$13*B8)+Inputs!$B$12*B8)*100000/Inputs!$B$7,2) -> 4.89 | C9: =ROUND((PMT(Inputs!$B$11,Inputs!$B$6,-C8,Inputs!$B$15*C8)+Inputs!$B$12*C8)*100000/Inputs!$B$7,2) -> 3.04 | D9: =ROUND((PMT(Inputs!$B$11,Inputs!$B$6,-D8,Inputs!$B$14*D8)+Inputs!$B$12*D8)*100000/Inputs!$B$7,2) -> 4.81
A10: TOTAL (₹/km) | B10: =B5+B6+B7+B9 -> 10.09 | C10: =C5+C6+C7+C9 -> 7.06 | D10: =D5+D6+D7+D9 -> 7.23
A11: Uplift vs CNG (₹/month) | B11: =0 -> 0 | C11: =(B10-C10)*Inputs!$B$7/12 -> 15150 | D11: =(B10-D10)*Inputs!$B$7/12 -> 14300
A13: By 2035 the Tour-e + BaaS runs ~₹3/km below today's CNG benchmark: ~₹15k/month for an owner-driver.

Sheet Sources
A1: Sources used in the model
A2: Accessed Sep 2026. Team assumptions are labelled on the Inputs sheet.
A4: # | B4: Source | C4: Data used | D4: Link
A5: 1 | B5: Maruti Suzuki press release (Feb 2026) | C5: e VITARA BaaS ₹10.99 L + ₹3.99/km; retail BaaS usage basis | D5: https://www.marutisuzuki.com/corporate/media/press-releases/2026/february/india-goes-electric-with-maruti-suzuki-e-vitara-introductory-baas-price-starts
A6: 2 | B6: Autocar India – BaaS prices of e Vitara explained | C6: Pack value ~₹5 L (49 kWh); 1,800 km/month minimum | D6: https://www.autocarindia.com/auto-features/baas-prices-of-maruti-e-vitara-explained-440247
A7: 3 | B7: Autocar India – Maruti prices after GST cuts (Sep 2025) | C7: Ertiga Tour M CNG post-GST ex-showroom | D7: https://www.autocarindia.com/car-news-amp/maruti-suzuki-prices-after-gst-cuts-the-swift-gets-a-lakh-cheaper-437189
A8: 4 | B8: Outlook Business – Delhi CNG ₹86.98/kg | C8: CNG price, Aug–Sep 2026 | D8: https://www.outlookbusiness.com/economy-and-policy/delhi-cng-to-cost-8698kg-as-igl-passes-on-rising-lng-costs
A9: 5 | B9: BloombergNEF – 2025 battery price survey | C9: Pack prices: global $108/kWh; China $84/kWh; LFP $81/kWh | D9: https://about.bnef.com/insights/clean-transport/lithium-ion-battery-pack-prices-fall-to-108-per-kilowatt-hour-despite-rising-metal-prices-bloombergnef/
A10: 6 | B10: ClearTax – GST on cars (GST 2.0) | C10: EV 5%; >4 m petrol/CNG 40%, from 22 Sep 2025 | D10: https://cleartax.in/s/gst-on-cars
A11: 7 | B11: CEEW (2025) – Cost of ownership for road transport | C11: EVs cheapest-to-own taxi option; CNG next | D11: https://www.ceew.in/publications/cost-of-ownership-for-road-transport-sector-for-different-vehicle-segments-fuels-and-powertrains
A12: 8 | B12: MeraEV – EV charging cost in India (2026) | C12: Public DC tariff range | D12: https://www.meraev.com/blog/ev-charging-cost-in-india-full-guide
A13: 9 | B13: MyMotor – state-wise EV charging tariffs | C13: Depot / EV tariff range | D13: https://www.mymotor.in/blog/ev-charging-cost-india-state-wise-tariff
A14: 10 | B14: HDFC Sky – INR/USD daily reports (Jun–Aug 2026) | C14: Exchange rate ~₹95/$ | D14: https://hdfcsky.com/news/inr-usd-rate-august-11-2026-rupee-falls-95-43
A15: 11 | B15: Rushlane – Ertiga CNG launch | C15: Claimed 26.11 km/kg CNG efficiency | D15: https://www.rushlane.com/2019-maruti-ertiga-cng-launched-12318513.html
